Workbook

Sheet 需求概述
B1: 序号 | C1: 需求模块 | D1: 模块处理逻辑说明 | E1: 备注
B2: 1 | C2: 往来账龄模块
B3: 2 | C3: 坏账计算逻辑
B4: 3 | C4: 周转分析模块

Sheet 需求总览
B1: 序号 | C1: 需求分类 | D1: 需求小类 | E1: 需求点 | F1: 需求响应（满足/不满足） | G1: PRD文档位置（sheet页） | H1: PRD关键逻辑描述 | I1: 备注 | K1: 0908：后续沟通确认一个统一的梳理的模版
B2: 1 | C2: 维度映射 | D2: 一/二/三级公司分类 | E2: 往来账龄明细表、应收账款周转分析明细表新增【一/二/三级公司分类】字段，按客户主数据取值；营销客户主数据未上线公司（日立、商冷、激光、古洛尼、雅士高、显示基地、冰冷洗基地、空气基地、其他公司）字段置空 | F2: 满足 | G2: dwd_fi_mr_arap_detail_mi | H2: DWD层进行维度映射处理
B3: 2 | C3: 维度映射 | D3: 利润中心映射 | E3: 维护"老利润中心→新利润中心"映射关系；范围限于应收账款清账口径利润中心（《应收维度统计表-利润中心对应关系表（新）》）；涉及电商本次不清洗客户清单 | F3: 满足 | G3: dwd_fi_mr_arap_detail_mi | H3: DWD层进行维度映射处理
B4: 3 | C4: 维度映射 | D4: 渠道分组映射 | E4: 维护"一级/三级公司分类→渠道分组"映射（含下沉/零售/零售-传统零售/零售-新零售/转口贸易/外售）；按优先级：天猫优品/京东专卖/苏宁零售云映射下沉；一级=电商映射零售；一级≠电商映射零售-传统零售 | F4: 满足 | G4: dwd_fi_mr_arap_detail_mi | H4: DWD层进行维度映射处理
B5: 4 | C5: 维度新增 | D5: 业务范围 | E5: 坏账计提凭证入账、传输损益表新增【业务范围】字段；通用规则按《业务范围配置表》；特殊规则：6210 按三级性质映射、1180/12**按客户主数据二级公司分类、商用显示按国家-业务范围映射、日立按国家-大区映射 | F5: 满足 | G5: dwd_fi_mr_arap_detail_mi | H5: DWD层进行维度映射处理
B6: 5 | C6: 维度映射 | D6: 业务管理单元 | E6: 空气事业部管报新增【业务管理单元】字段：SAP600 通过利润中心映射、SAP700 默认 ZZZZ、SAP900 通过三级性质映射（煤改电/OEM/网络能源/其他） | F6: 满足 | G6: dwd_fi_mr_arap_detail_mi | H6: DWD层进行维度映射处理
B7: 6 | C7: 维度新增 | D7: 周转分析渠道 | E7: 应收账款周转分析明细表新增【一/二/三级渠道】字段；上线公司按"渠道分组"+二/三级公司分类映射，未上线公司（除日立、商冷特殊规则）默认缺省值 ZZZZ | F7: 满足 | G7: dwd_fi_mr_arap_detail_mi | H7: DWD层进行维度映射处理
B8: 7 | C8: 维度新增 | D8: MDG 商冷客户群映射 | E8: 6380、6797商冷三级渠道 → MDG【商冷客户群】映射 | F8: 待维度定标
B9: 8 | C9: D 表数据源新增 | D9: 应收账面数据源 | E9: D 表新增"①SAP 应收货款账面余额"字段：来源 SAP600/700/800/900/810（应收账款、合同资产、合同负债、其他应收款、长期应收款-信汇）； | F9: 满足 | G9: dwd_fi_mr_arap_detail_mi | H9: DWD层复刻SAPZZT003的逻辑取底表数据计算账龄天数
B10: 9 | C10: D 表数据源新增 | D10: 调整项数据源 | E10: "②期末出库未开（不含税）"：来源管报 2.0 收入出库未开底稿，仅涉及冰冷洗营销、空气营销；新增"③期末退货未办退税（不含税）"：来源管报 2.0 收入退货未办底稿，涉及冰冷洗营销、空气营销；账龄均放置在 1 个月以内 | F10: 满足 | G10: ARP001_STEP_1 | H10: 在M层直接取收入M01表中的出库和退货的数据
B11: 10 | C11: D 表数据源新增 | D11: 超期款数据源 | E11: D 表新增【超期金额】字段：来源财务中台-问题资金系统，按账套取客户+利润中心/客户超期款金额；显示/激光/冰冷/空气/古洛尼/厨卫事业部需分别确认范围与字段口径（含商显2080、冰冷商冷 6380/6797、空气日立1730-1761、维保、模具等明细） | F11: 满足 | G11: dwd_fi_mr_ar_overdue_mi | H11: 取财务中台-问题资金系统中超期款及开票样机的金额，以及超期款调整口的数据
B12: 11 | C12: D 表数据源新增 | D12: 返利数据源 | E12: D 表新增【已确认未兑现返利余额】：来源政策系统（显示/冰箱/空气营销）、SMS（日立）、FBL5N（SAP600 未清明细）；日立口径以 SMS经销商返利余额为准 | F12: 满足 | G12: dwd_fi_mr_ar_ureb_mi | H12: 取SMS系统、政策系统、SAP系统的欠付返利明细
B13: 12 | C13: D 表数据源新增 | D13: 欠付费用数据源 | E13: D 表新增【已账扣未报账欠付费用】：来源 SAP600，主要覆盖显示/冰冷/空气营销公司，账龄放置在 1 个月以内 | F13: 满足 | G13: ARP001_STEP_1 | H13: 将往来账龄及周转影响因素需要的数据聚合到计算底稿中，包括SAP的账龄明细、信汇明细、出库未开、退货未办、超期款数据、提前回款、电商零售节奏、欠付费用、欠付返利，通过数据分类字段区分开
B14: 12 | C14: D 表数据源新增 | D14: 提前回款数据源 | E14: 新增提前回款的取数逻辑，作为周转分析的影响因素 | F14: 满足 | G14: ARP001_STEP_1 | H14: 将往来账龄及周转影响因素需要的数据聚合到计算底稿中，包括SAP的账龄明细、信汇明细、出库未开、退货未办、超期款数据、提前回款、电商零售节奏、欠付费用、欠付返利，通过数据分类字段区分开
B15: 12 | C15: D 表数据源新增 | D15: 电商零售数据源 | E15: 新增电商销售零售的取数逻辑，作为周转分析的影响因素 | F15: 满足 | G15: ARP001_STEP_1 | H15: 将往来账龄及周转影响因素需要的数据聚合到计算底稿中，包括SAP的账龄明细、信汇明细、出库未开、退货未办、超期款数据、提前回款、电商零售节奏、欠付费用、欠付返利，通过数据分类字段区分开
B16: 13 | C16: D 表数据源新增 | D16: 核销金额数据源 | E16: D表新增财务中台核销金额数据源取数 | F16: 满足 | G16: dwd_fi_mr_ar_writeoff_mi | H16: 取财务中台中坏账核销单中的核销金额数据
B17: 14 | C17: D 表数据源新增 | D17: 国际营销占用数据源 | E17: D表新增国际营销占用取数 | F17: 满足 | G17: dwd_fi_mr_ar_imocc_mi | H17: 取信数系统中国际营销对外的的应收占用数据
B18: 15 | C18: D 表数据源新增 | D18: 账期数据源 | E18: D 表新增【账期】字段：取 SAP-KNB1 付款条件编码，通过 SAP-T052 解释 | F18: 满足 | G18: dwd_fi_mr_ar_cterm_md | H18: 根据SAP的客户主数据相关表单，匹配处理成每个客户的付款条件明细信息
B19: 16 | C19: D/M/S 表逻辑处理 | D19: 账龄进数范围限制 | G19: ARP001_STEP_2 | H19: 往来账龄需要对部分客商或科目等进行剔除，此步骤用于将步骤1取到的数据根据进数范围进行限制
B20: 17 | C20: D/M/S 表逻辑处理 | D20: 重分类 | E20: 法人口径重分类、管理口径重分类、分公司管理口径重分类三个口径的重分类判断规则 | F20: 满足 | G20: ARP001_STEP_3 | H20: 此步骤将往来账龄的数据根据重分类的规则进行重分类的判断，法人口径、管理口径、管理分公司口径三个口径的重分类处理，以及集团归属范围的判断
B21: 18 | C21: D/M/S 表逻辑处理 | D21: 合同负债税额剔除 | F21: 满足 | G21: ARP002_STEP_1 | H21: 此表将往来账龄计算底稿不同数据分类的数据平铺到列上展示，并且针对应收重分类到合同负债的数据，把对应的税额剔除
B22: 19 | C22: D/M/S 表逻辑处理 | D22: 坏账计提基数表 | E22: 指标=调整后应收账款，公式=①SAP 应收+②出库未开-③退货未办-④直销垫资-⑤保证金-⑥海外投保 | F22: 满足 | G22: ARP003_STEP_1 | H22: 将往来账龄表中涉及到需要计算坏账的数据取到坏账计算表中，根据管理分类和分公司分类不同生成两个口径的数据，并且匹配出坏账的调整项，如果有直销垫资的金额，用垫资的金额冲减坏账计提基数，优先从长账龄冲销，如果同一个客户存在负数的账龄金额，拆分到长账龄的区间中
B23: 20 | C23: D/M/S 表逻辑处理 | D23: 坏账计提基数调整优先级 | E23: 基数计算按"个别认定表（优先级1）> 投保信息录入表免赔额（优先级2）> 账龄表-手工调整项（优先级3）" | F23: 满足 | G23: ARP003_STEP_2 | H23: 根据不同的坏账计提规则计算坏账金额，如果有个别认定和煤改电，优先取对应的金额计提坏账，再按照优先级匹配坏账计提比例，根据坏账计提比例*坏账计提基数计算坏账金额，如果保障天数>0，需要再根据保障天数判断坏账计提区间，根据坏账计提比例*坏账计提基数*未覆盖比例计算坏账
B24: 21 | C24: D/M/S 表逻辑处理 | D24: 管理口径坏账计提 | E24: 调整后应收账款中预收余额利润中心使用先进先出法分配至账龄段，按账套+客户+利润中心计算坏账；预收利润中心坏账按"应收利润中心坏账金额/Σ同客户应收利润中心坏账金额"分摊至应收利润中心； | F24: 满足 | G24: ARP003_STEP_3 | H24: 针对坏账计算出来为负数的行项目，按照同一个公司+客户+科目计算正数行的比例，把负数的坏账金额分摊到正数行上
B25: 22 | C25: D/M/S 表逻辑处理 | D25: 应收占用指标重构 | E25: 应收占用=应收账款账面余额+期末出库未开-期末退货未办退税-集团内应收货款占用-虚拟售料外协厂应收余额-应收信汇占用-垫资款+管理口径跨事业部应收占用；剔除项含电视/空调对中国区挂外部户的70012338、虚拟售料外协厂、信汇（1122000095/1131000095）等 | F25: 满足 | G25: ARP004_STEP_1 | H25: 把往来账龄结果表的数据筛选出需要计算周转的应收占用数据，根据取数配置表中的限制进行数据的取数及剔除，以及将手工调整的影响因素也匹配到同一行数据中
B26: 24 | C26: D/M/S 表逻辑处理 | D26: 周转影响因素拆解 | E26: 周转分析表拆解 8 类影响因素：①超期款金额、②提前回款金额、③电商零售销售节奏、④已确认未兑现返利、⑤已账扣未报账欠付费用、⑥开票样机额度、⑦国补未回款影响、⑧手工导入因素 | F26: 满足 | G26: ARP004_STEP_1 | H26: 把往来账龄结果表的数据筛选出需要计算周转的应收占用数据，根据取数配置表中的限制进行数据的取数及剔除，以及将手工调整的影响因素也匹配到同一行数据中
B27: 25 | C27: D/M/S 表逻辑处理 | D27: 主营业务收入指标重构 | E27: 收入=开票收入+期末出库未开-期末退货未办退税-当月计提返利-集团内客户收入+管理口径跨事业部应收占用；剔除项含业绩调拨调入/调出、小 B 国补业务数据冲销/还原 | F27: 满足 | G27: ARP005_STEP_1 | H27: 把单体销售明细表的数据筛选出需要计算周转的收入数据，根据取数配置表中的限制进行数据的取数及剔除
B28: 23 | C28: D/M/S 表逻辑处理 | D28: 利润中心跨事业部拆分 | E28: 同一账套同一客户跨事业部时，只取拆分事业部后>0 的金额（如冰冷/洗护、显示/激光） | F28: 满足 | G28: ARP001_STEP_1 | H28: 将周转计算的占用和收入的M表匹配成一个表单，匹配出对应的事业部维度，将不符合条件的数据进行排除
B29: 24 | C29: D/M/S 表逻辑处理 | D29: 周转表-指标表维度映射 | E29: 周转表与指标表维度对应关系，作为指标表推送规则说明 | F29: 满足 | G29: ARP002_STEP_1 | H29: 根据配置表维护的周转口径的对应关系将指标表需要展示的周转口径的数据计算后同步到核心利润S表中
B30: 25 | C30: 展示报表需求 | D30: 期末汇率余额 | E30: D 表新增【期末汇率余额】【记账汇率余额】【汇率评估方式】【理论汇兑评估】字段，逻辑同管报 1.0
B31: 26 | C31: 展示报表需求 | D31: 调整后返利/退货 | E31: D 表新增【调整后返利】（冰箱专用，67**）与【调整后退货】（显示专用，26**/23**/1632）字段，由公式按应收账面余额与返利/退货余额比较后计算
B32: 27 | C32: 展示报表需求 | D32: 一级/二级/三级性质 | E32: 往来账龄明细表新增【一级/二级/三级性质】字段；一级/二级来源管报 1.0 配置表（B20_0101_02），三级手工填写并联动一级
B33: 28 | C33: 展示报表需求 | D33: 利润中心校验 | E33: 账龄表增加利润中心系统校验：原则上仅允许出现应收账款清账口径利润中心；出现新增利润中心时需提示，报表人调账处理
B34: 29 | C34: 展示报表需求 | D34: 账龄段颜色提示 | E34: 科目余额为正且出现负数账龄时，将负数账龄单元格标记特殊颜色
B35: 30 | C35: 展示报表需求 | D35: 余额三项校验 | E35: 管报 2.0 账龄表新增校验表，校验：①管报 1.0 账龄表、②管报 2.0 账龄表明细表、③管报 1.0 资产负债表科目余额
B36: 31 | C36: 展示报表需求 | D36: 客户/供应商冲突标记 | E36: 同一账套下既为客户又为供应商（名称相同）且本期余额不为 0 时，对应单元格标记颜色
B37: 32 | C37: 展示报表需求 | D37: 是否存续字段联动 | E37: 同一账套下【是否存续】字段填写后，结果附用至同客商（客户与供应商名称相同）
B38: 33 | C38: 展示报表需求 | D38: 应收账款周转分析表-事业部 | E38: 4.5.1：中国区、显示、激光、冰冷、洗护、空气、厨电、古洛尼、雅士高事业部层级周转指标（按账套+客户维度重分类）
B39: 34 | C39: 展示报表需求 | D39: 应收账款周转分析表-单体法人 | E39: 4.5.1：按账套维度出具应收账款周转指标（按账套+客户维度重分类）
B40: 35 | C40: 展示报表需求 | D40: 应收账款周转分析表-分公司 | E40: 4.5.1+4.5.3：电冰空等分公司层级周转指标（按账套+客户+利润中心加严口径），另含 S 表"应收账款周转分析展示表-分公司"

Sheet 0.0 ODS目录
B1: 入湖及数据更新情况列的统计时间是20260907 问题1：很多sap的表分了好几套，ODSS600/ODS_S600/ODSSLT_S600/ODS_SLT_S600，需要确定使用哪些表，需要每个表都确定 问题2：有些是空表，以及更新时间不是最新的 问题3：没有表的需要进行入湖 | K1: 高频抽数（月结）： 主数据类：1-6号，6点开始，每6小时一次 明细项类：1-6号，每小时一次 低频抽数： 其他日期，每日0点抽一次
C2: 黄底为入湖中的表 | I2: 统计日期为20260907 | K2: 抽数频率后续要统一查下，尤其SAP的账期明细变动相关表
B3: 分层 | C3: 编码 | D3: 数据库表名 | E3: 名称 | F3: 用途 | G3: 来源 | H3: 备注 | I3: 入湖及数据更新情况（load_dt为入湖规范中的数据入湖时间） | J3: 最终贴源表 | K3: 抽数调度任务 | L3: 入湖进度
B4: ods | C4: odss600_knb1 | D4: =B4&"."&C4 | E4: 公司客户主数据 | F4: 取客户对应的账期 | G4: SAP | I4: 最新load_dt为20260907 | L4: 无
B5: ods | C5: odss700_knb1 | D5: =B5&"."&C5 | E5: 公司客户主数据 | F5: 取客户对应的账期 | G5: SAP | I5: 最新load_dt为20260907 | L5: 无
B6: ods | C6: odss800_knb1 | D6: =B6&"."&C6 | E6: 公司客户主数据 | F6: 取客户对应的账期 | G6: SAP | I6: 最新load_dt为20260907 | L6: 无
B7: ods | C7: odss900_knb1 | D7: =B7&"."&C7 | E7: 公司客户主数据 | F7: 取客户对应的账期 | G7: SAP | I7: 最新load_dt为20260907 | L7: 无
B8: ods | C8: odss610_knb1 | D8: =B8&"."&C8 | E8: 公司客户主数据 | F8: 取客户对应的账期 | G8: SAP | I8: 最新load_dt为20260907 | L8: 无
B9: ods | C9: odss810_knb1 | D9: =B9&"."&C9 | E9: 公司客户主数据 | F9: 取客户对应的账期 | G9: SAP | I9: 最新load_dt为20260907 | L9: 无
B10: ods | C10: odss600_t052u | D10: =B10&"."&C10 | E10: 付款条件主数据 | F10: 取客户对应的账期 | G10: SAP | H10: 需要统一提一下入湖工单，让大数据团队进行数据入湖 | I10: 空表 | J10: odss600_t052u | K10: 离线任务名：ds1182_ODSS600_T052U 自动调度名：DS_S600@D_1-31_0抽数来源：EDW_STG--STG.S600_T052U | L10: 抽数调度已配，DORIS已查询到当日数据
B11: ods | C11: odss700_t052u | D11: =B11&"."&C11 | E11: 付款条件主数据 | F11: 取客户对应的账期 | G11: SAP | H11: 需要统一提一下入湖工单，让大数据团队进行数据入湖 | I11: 空表 | J11: odss700_t052u | K11: 离线任务名：ds5765_ODSS700_T052U 自动调度名：DS_S700@D_1-31_0抽数来源：EDW_STG--STG.S700_T052U | L11: 抽数调度已配，DORIS已查询到当日数据
B12: ods | C12: odss800_t052u | D12: =B12&"."&C12 | E12: 付款条件主数据 | F12: 取客户对应的账期 | G12: SAP | H12: 需要统一提一下入湖工单，让大数据团队进行数据入湖 | I12: 空表 | J12: odss800_t052u | K12: 离线任务名：ds4873_ODSS800_T052U 自动调度名：DS_S800@D_1-31_0抽数来源：EDW_STG--STG.S800_T052U | L12: 抽数调度已配，最新数为当日8点抽取
B13: ods | C13: odss900_t052u | D13: =B13&"."&C13 | E13: 付款条件主数据 | F13: 取客户对应的账期 | G13: SAP | H13: 需要统一提一下入湖工单，让大数据团队进行数据入湖 | I13: 空表 | K13: 离线任务名：ds6769_ODSS900_T052U 自动调度名：DS_S900@D_1-31_0抽数来源：EDW_STG--STG.S900_T052U | L13: 入湖流程中
B14: ods | C14: odss610_t052u | D14: =B14&"."&C14 | E14: 付款条件主数据 | F14: 取客户对应的账期 | G14: SAP | H14: 需要统一提一下入湖工单，让大数据团队进行数据入湖 | I14: 没有表 | J14: odss610_t052u | K14: 无 | L14: 抽数调度已配，DORIS已查询到当日数据
B15: ods | C15: odss810_t052u | D15: =B15&"."&C15 | E15: 付款条件主数据 | F15: 取客户对应的账期 | G15: SAP | H15: 需要统一提一下入湖工单，让大数据团队进行数据入湖 | I15: 最新load_dt为20260730 | J15: odss810_t052u | K15: 无 | L15: 抽数调度已配，DORIS已查询到当日数据
B16: ods | C16: odsslt_s600_bsid | D16: =B16&"."&C16 | E16: 客户‌未清‌项表 | F16: 计算客户对应的应收账龄明细 | G16: SAP | I16: 最新load_dt为20260907 | L16: 无
B17: ods | C17: odsslt_s600_bsad | D17: =B17&"."&C17 | E17: 客户‌已清‌项表 | F17: 计算客户对应的应收账龄明细 | G17: SAP | I17: 最新load_dt为20260907 | L17: 无
B18: ods | C18: odsslt_s600_bsik | D18: =B18&"."&C18 | E18: 供应商‌未清‌项表 | F18: 计算供应商对应的应收账龄明细 | G18: SAP | I18: 最新load_dt为20260907 | L18: 无
B19: ods | C19: odsslt_s600_bsak | D19: =B19&"."&C19 | E19: 供应商‌已清‌项表 | F19: 计算供应商对应的应收账龄明细 | G19: SAP | I19: 最新load_dt为20260907 | L19: 无
B20: ods | C20: odss600_lfa1 | D20: =B20&"."&C20 | E20: 供应商主数据 | G20: SAP | I20: 最新load_dt为20260907 | L20: 无
B21: ods | C21: ods_slt_s600_kna1 | D21: =B21&"."&C21 | E21: 客户主数据 | G21: SAP | I21: 最新load_dt为20260907 | L21: 无
B22: ods | C22: odsslt_s610_bsid | D22: =B22&"."&C22 | E22: 客户‌未清‌项表 | F22: 计算客户对应的应收账龄明细 | G22: SAP | H22: 如果要用610系统的SLT表，直接从810的SLT表取值即可，mandt='610' | I22: 没有表，只有ods.odss600_bsid且为空表
B23: ods | C23: odsslt_s610_bsad | D23: =B23&"."&C23 | E23: 客户‌已清‌项表 | F23: 计算客户对应的应收账龄明细 | G23: SAP | H23: 如果要用610系统的SLT表，直接从810的SLT表取值即可，mandt='610' | I23: 没有表，只有ods.odss600_bsad且为空表
B24: ods | C24: odsslt_s610_bsik | D24: =B24&"."&C24 | E24: 供应商‌未清‌项表 | F24: 计算供应商对应的应收账龄明细 | G24: SAP | H24: 如果要用610系统的SLT表，直接从810的SLT表取值即可，mandt='610' | I24: 没有表，只有ods.odss600_bsik且为空表
B25: ods | C25: odsslt_s610_bsak | D25: =B25&"."&C25 | E25: 供应商‌已清‌项表 | F25: 计算供应商对应的应收账龄明细 | G25: SAP | H25: 如果要用610系统的SLT表，直接从810的SLT表取值即可，mandt='610' | I25: 没有表，只有ods.odss600_bsak且为空表
B26: ods | C26: odss610_lfa1 | D26: =B26&"."&C26 | E26: 供应商主数据 | G26: SAP | H26: 需要统一提一下入湖工单，让大数据团队进行数据入湖 | I26: 最新load_dt为20260906 | J26: odss610_lfa1 | K26: 离线任务名：ds251_ODSS610_LFA1 自动调度名：PUB_S610@D_1-31_22抽数来源：EDW_STG--stg.S610_LFA1 | L26: 抽数调度已配，DORIS已查询到当日数据
B27: ods | C27: ods_slt_s610_kna1 | D27: =B27&"."&C27 | E27: 客户主数据 | G27: SAP | H27: 如果要用610系统的SLT表，直接从810的SLT表取值即可，mandt='610' | I27: 没有表，只有odss610_kna1且最新load_dt为20260907
B28: ods | C28: odsslt_s700_bsid | D28: =B28&"."&C28 | E28: 客户‌未清‌项表 | F28: 计算客户对应的应收账龄明细 | G28: SAP | I28: 最新load_dt为20260907 | L28: 无
B29: ods | C29: odsslt_s700_bsad | D29: =B29&"."&C29 | E29: 客户‌已清‌项表 | F29: 计算客户对应的应收账龄明细 | G29: SAP | I29: 最新load_dt为20260907 | L29: 无
B30: ods | C30: odsslt_s700_bsik | D30: =B30&"."&C30 | E30: 供应商‌未清‌项表 | F30: 计算供应商对应的应收账龄明细 | G30: SAP | I30: 最新load_dt为20260907 | L30: 无
B31: ods | C31: odsslt_s700_bsak | D31: =B31&"."&C31 | E31: 供应商‌已清‌项表 | F31: 计算供应商对应的应收账龄明细 | G31: SAP | I31: 最新load_dt为20260907 | L31: 无
B32: ods | C32: odss700_lfa1 | D32: =B32&"."&C32 | E32: 供应商主数据 | G32: SAP | I32: 最新load_dt为20260907 | L32: 无
B33: ods | C33: ods_slt_s700_kna1 | D33: =B33&"."&C33 | E33: 客户主数据 | G33: SAP | I33: 最新load_dt为20260907 | L33: 无
B34: ods | C34: odsslt_s800_bsid | D34: =B34&"."&C34 | E34: 客户‌未清‌项表 | F34: 计算客户对应的应收账龄明细 | G34: SAP | I34: 最新load_dt为20260907 | L34: 无
B35: ods | C35: odsslt_s800_bsad | D35: =B35&"."&C35 | E35: 客户‌已清‌项表 | F35: 计算客户对应的应收账龄明细 | G35: SAP | I35: 最新load_dt为20260907 | L35: 无
B36: ods | C36: odsslt_s800_bsik | D36: =B36&"."&C36 | E36: 供应商‌未清‌项表 | F36: 计算供应商对应的应收账龄明细 | G36: SAP | H36: 需要统一提一下入湖工单，让大数据团队进行数据入湖 | I36: 没有表，只有odss800_bsik且最新load_dt为20260907 | J36: odss800_bsik | K36: 离线任务名：ds1414_ODSS800_BSIK 自动调度名：PUB_S800@D_1-31_22、DS_S800@D_1-31_0抽数来源：EDW_STG--STG.S800_BSIK | L36: 调度已配置，最新数为21日0点抽取
B37: ods | C37: odsslt_s800_bsak | D37: =B37&"."&C37 | E37: 供应商‌已清‌项表 | F37: 计算供应商对应的应收账龄明细 | G37: SAP | I37: 最新load_dt为20260907 | L37: 无
B38: ods | C38: odss800_lfa1 | D38: =B38&"."&C38 | E38: 供应商主数据 | G38: SAP | I38: 最新load_dt为20260907 | L38: 无
B39: ods | C39: ods_slt_s800_kna1 | D39: =B39&"."&C39 | E39: 客户主数据 | G39: SAP | H39: 需要统一提一下入湖工单，让大数据团队进行数据入湖 | I39: 没有表，只有odss800_kna1且最新load_dt为20260907 | J39: odss800_kna1 | K39: 离线任务名：py_ODSS800_KNA1_2ds 自动调度名：DS_S800@D_1-31_0、S800@H2_L1-6_2抽数来源：EDW_STG--STG.S800_KNA1 | L39: 入湖流程中，ods_slt_s800b_kna1已有当日数据，但比odss800_kna1少记录数
B40: ods | C40: odsslt_s810_bsid | D40: =B40&"."&C40 | E40: 客户‌未清‌项表 | F40: 计算客户对应的应收账龄明细 | G40: SAP | I40: 最新load_dt为20260907 | L40: 无
...

Sheet ods表详情
A1: 表名 | B1: 表字段名 | C1: 字段描述
A2: odss600_kna1 | B2: mandt | C2: 客户端
A3: odss600_kna1 | B3: kunnr | C3: 客户编号
A4: odss600_kna1 | B4: land1 | C4: 国家代码
A5: odss600_kna1 | B5: name1 | C5: 名称11
A6: odss600_kna1 | B6: name2 | C6: 名称21
A7: odss600_kna1 | B7: ort01 | C7: 城市
A8: odss600_kna1 | B8: pstlz | C8: 邮政编码
A9: odss600_kna1 | B9: regio | C9: 地区（省/自治区/直辖市、市、县）
A10: odss600_kna1 | B10: sortl | C10: 排序字段
A11: odss600_kna1 | B11: stras | C11: 住宅号及街道
A12: odss600_kna1 | B12: telf1 | C12: 第一个电话号
... A170: odss600_kna1 | B170: psoo5 | C170: 描述1
A171: odss600_kna1 | B171: load_dt
A172: odss600_kna1 | B172: zkunnr_mdg | C172: MDG客户编码
A173: odss600_kna1 | B173: zname1_mdg | C173: MDG客户名称
A174: odss600_kna1 | B174: zname3_mdg | C174: MDG英文名称
A175: odss600_kna1 | B175: zzcvco
A176: odss600_knb1 | B176: mandt | C176: 客户端
A177: odss600_knb1 | B177: kunnr | C177: 客户编号
A178: odss600_knb1 | B178: bukrs | C178: 公司代码
A179: odss600_knb1 | B179: pernr | C179: 人员编号
A180: odss600_knb1 | B180: erdat | C180: 记录创建日期
A181: odss600_knb1 | B181: ernam | C181: 创建对象的人员名称
A182: odss600_knb1 | B182: sperr | C182: 对公司代码过帐冻结
A183: odss600_knb1 | B183: loevm | C183: 主记录删除标记(公司代码级)
A184: odss600_knb1 | B184: zuawa | C184: 根据分配号排序代码
A185: odss600_knb1 | B185: busab | C185: 会计职员
A186: odss600_knb1 | B186: akont | C186: 总帐中的统驭科目
A187: odss600_knb1 | B187: begru | C187: 权限组
... A252: odss600_knb1 | B252: gmvkzd | C252: 正在执行客户
A253: odss600_knb1 | B253: load_dt
A254: odss600_t052u | B254: mandt | C254: 客户端
A255: odss600_t052u | B255: spras | C255: 语言代码
A256: odss600_t052u | B256: zterm | C256: 付款条件代码
A257: odss600_t052u | B257: ztagg | C257: 天数限制
A258: odss600_t052u | B258: text1 | C258: 收付条款的自解释
A259: odss600_t052u | B259: load_dt
A260: odss600_bsid | B260: mandt | C260: 客户端
A261: odss600_bsid | B261: bukrs | C261: 公司代码
...

Sheet 1. DWD逻辑处理--》》

Sheet 1. 0 DWD层目录
B1: DWD层
B3: 编码 | C3: 名称 | D3: 处理逻辑 | E3: MRD需求 | F3: 表单所属层级 | G3: 来源
B4: dwd_fi_mr_ar_cterm_md | C4: 客户账期明细表 | D4: 根据SAP的客户主数据相关表单，匹配处理成每个客户的付款条件明细信息 | E4: 账期取数 | F4: DWD-标准层 | G4: S600,700,800,900,610,810 | H4: 0908：目前数据是实时的，如果重新出表会按最新的主数据来匹配
B5: dwd_fi_mr_arap_detail_mi | C5: 往来账龄明细表 | D5: 根据SAP的底表处理到凭证编码的行项目明细，计算每行数据的账龄天数，并对维度进行映射处理 | E5: 往来账龄取数 | F5: DWD-标准层 | G5: S600,700,800,900,610,810
B6: dwd_fi_mr_arap_sum_mi | C6: 往来账龄汇总表 | D6: 根据detail的明细表单将数据进行聚合，不到凭证行项目，减少数据量，并且将信汇系统、超期款、欠付返利的数据聚合到一个表单中 | F6: DWD-汇总层
B7: dwd_fi_mr_ar_overdue_mi | C7: 超期款明细表 | D7: 取财务中台-问题资金系统中超期款及开票样机的金额，以及超期款调整口的数据 | E7: 超期金额取数 | F7: DWD-标准层 | G7: 财务中台-问题资金系统
B8: dwd_fi_mr_ar_ureb_mi | C8: 欠付返利明细表 | D8: 取SMS系统、政策系统、SAP系统的欠付返利明细 | E8: 返利余额取数 | F8: DWD-标准层 | G8: SMS系统、政策系统
B9: dwd_fi_mr_ar_imocc_mi | C9: 国际营销应收占用明细表 | D9: 取信数系统中国际营销对外的的应收占用数据 | E9: 应收占用-国际营销取数 | F9: DWD-标准层 | G9: 信数系统
B10: dwd_fi_mr_ar_writeoff_mi | C10: 核销金额明细表 | D10: 取财务中台中坏账核销单中的核销金额数据 | E10: 核销金额取数 | F10: DWD-标准层 | G10: 财务中台

Sheet dwd_fi_mr_ar_cterm_md
A1: 返回 | B1: dwd_fi_mr_ar_cterm_md逻辑处理
A2: 规则库 | B2: 表名称 | C2: dwd.dwd_fi_mr_ar_cterm_md
B3: 表描述 | C3: 客户账期明细表 | D3: 表类型 | E3: 事实表 | F3: 数仓分层 | G3: DWD
B4: L1数仓目录 | C4: 管理财经 | D4: L2数仓目录 | E4: 财报管理 | F4: L3数仓目录 | G4: 应收
B5: 更新方式 | C5: 全量更新 | D5: 设计人员 | F5: 时间
B6: 使用场景 | C6: 根据SAP的客户主数据相关表单，匹配处理成每个客户的付款条件明细信息
B7: 目标表 | M7: 客户主数据相关表单
B8: 字段中文名称 | C8: *字段名称 | D8: *类型 | E8: 主键 | F8: *描述 | G8: 允许为空 | H8: 默认值 | I8: 聚合类型 | J8: 基础标准 | K8: 标准代码 | L8: *安全分级 | M8: 转换清洗规则 | N8: 源系统 | O8: 源头表 | P8: 源头字段 | Q8: 匹配字段 | R8: 匹配过滤 | S8: 数仓处理脚本 | T8: 备注
B9: =IFERROR(VLOOKUP(C9,'字段信息'!A:C,3,),"") | C9: company_code | D9: =IFERROR(VLOOKUP(C9,'字段信息'!A:C,2,),"") | F9: =B9 | G9: √ | L9: 普通级 | M9: 直接对应 | N9: Doris | O9: odss600_knb1 odss700_knb1 odss800_knb1 odss900_knb1 odss610_knb1 odss810_knb1 ods.odsfima_aw_rul_revaaz_000001-SAP700公司映射表 | P9: bukrs | Q9: ods.odsfima_aw_rul_revaaz_000001
B10: 客户编码 | C10: cust_code | D10: =IFERROR(VLOOKUP(C10,'字段信息'!A:C,2,),"") | F10: =B10 | G10: √ | L10: 普通级 | M10: 直接对应 | N10: Doris | O10: odss600_knb1 odss700_knb1 odss800_knb1 odss900_knb1 odss610_knb1 odss810_knb1 | P10: kunnr
B11: =IFERROR(VLOOKUP(C11,'字段信息'!A:C,3,),"") | C11: pay_term_code | D11: =IFERROR(VLOOKUP(C11,'字段信息'!A:C,2,),"") | F11: =B11 | G11: √ | L11: 普通级 | M11: 如果对应多行的话拼成一行展示，用逗号分隔开 | N11: Doris | O11: odss600_knb1 odss700_knb1 odss800_knb1 odss900_knb1 odss610_knb1 odss810_knb1 | P11: zterm
B12: =IFERROR(VLOOKUP(C12,'字段信息'!A:C,3,),"") | C12: pay_term_desc | D12: =IFERROR(VLOOKUP(C12,'字段信息'!A:C,2,),"") | F12: =B12 | G12: √ | L12: 普通级 | M12: 如果对应多行的话拼成一行展示，用逗号分隔开 | N12: Doris | O12: odss600_t052u odss700_t052u odss800_t052u odss900_t052u odss610_t052u odss810_t052u | P12: text1 | Q12: zterm = zterm | R12: 限制语言SPRAS = '1'
B13: =IFERROR(VLOOKUP(C13,'字段信息'!A:C,3,),"") | C13: system_src | D13: =IFERROR(VLOOKUP(C13,'字段信息'!A:C,2,),"") | F13: =B13 | G13: √ | L13: 普通级 | M13: 直接对应 | N13: Doris | O13: odss600_knb1 odss700_knb1 odss800_knb1 odss900_knb1 odss610_knb1 odss810_knb1 | P13: 'S'||mandt
B14: =IFERROR(VLOOKUP(C14,'字段信息'!A:C,3,),"") | C14: load_dt | D14: =IFERROR(VLOOKUP(C14,'字段信息'!A:C,2,),"") | F14: =B14 | G14: √ | L14: 普通级 | M14: 数据更新时间 | N14: Doris

Sheet dwd_fi_mr_arap_detail_mi
A1: 返回 | B1: dwd_fi_mr_arap_detail_mi逻辑处理
A2: 规则库 | B2: 表名称 | C2: dwd.dwd_fi_mr_arap_detail_mi
B3: 表描述 | C3: 往来账龄明细表 | D3: 表类型 | E3: 事实表 | F3: 数仓分层 | G3: DWD
B4: L1数仓目录 | C4: 管理财经 | D4: L2数仓目录 | E4: 财报管理 | F4: L3数仓目录 | G4: 应收
B5: 更新方式 | C5: 增量更新 | D5: 设计人员 | F5: 时间
B6: 使用场景 | C6: 根据SAP的底表处理到凭证编码的行项目明细，计算每行数据的账龄天数
B7: 目标表 | M7: 客户、供应商行项目【BSID/BSAD/BSIK/BSAK】 | V7: 科目余额表【faglflext/glfunct】
B8: 字段中文名称 | C8: *字段名称 | D8: *类型 | E8: 主键 | F8: *描述 | G8: 允许为空 | H8: 默认值 | I8: 聚合类型 | J8: 基础标准 | K8: 标准代码 | L8: *安全分级 | M8: 转换清洗规则 | N8: 源系统 | O8: 源头表 | P8: 源头字段 | Q8: 匹配字段 | R8: 匹配过滤 | S8: 数仓处理脚本 | T8: 备注 | V8: 转换清洗规则 | W8: 源系统 | X8: 源头表 | Y8: 源头字段 | Z8: 匹配字段 | AA8: 匹配过滤 | AB8: 数仓处理脚本 | AC8: 备注
B9: =IFERROR(VLOOKUP(C9,'字段信息'!A:C,3,),"") | C9: dt_month | D9: =IFERROR(VLOOKUP(C9,'字段信息'!A:C,2,),"") | F9: =B9 | N9: 参数年月 | W9: 参数年月
B10: =IFERROR(VLOOKUP(C10,'字段信息'!A:C,3,),"") | C10: year | D10: =IFERROR(VLOOKUP(C10,'字段信息'!A:C,2,),"") | F10: =B10 | G10: √ | L10: 普通级 | M10: 限制条件： 1、凭证状态bstat 不为A,S 2、日期限制： bsid/bsik：budat小于等于参数的月末 bsad/bsak：budat小于等于参数的月末且augdt大于参数的月末 3、科目限制： 限制科目为统驭科目，科目范围ztzt_003表匹配公司账目t001表，获得公司和科目的范围，在通过公司总账科目skb1表获得是否是统驭科目，mitkz为D、K则为统驭科目 应收：bsid/bsad：科目类型为D 应付：bsik/bsak：科目类型为K 单独取BSAD中本月已清项目： augdt介于参数本月的日期中&rstgr = ‘400’ | N10: 参数年 | V10: 限制条件： 1、科目限制： 限制科目为非统驭科目，科目范围ztzt_003表匹配公司账目t001表，获得公司和科目的范围，在通过公司总账科目skb1表获得是否是统驭科目，mitkz为空则为非统驭科目 | W10: 参数年
B11: =IFERROR(VLOOKUP(C11,'字段信息'!A:C,3,),"") | C11: month | D11: =IFERROR(VLOOKUP(C11,'字段信息'!A:C,2,),"") | F11: =B11 | G11: √ | L11: 普通级 | M11: 直接对应 | N11: 参数月 | U11: 0908：审计调整的科目余额怎么取 和用户确认 | V11: 通过金额字段转换获得月份 1月等于：hslvt+hsl01 2月等于：hslvt+hsl01+hsl02 ... 12月等于：hslvt+hsl01+hsl02....+hsl12 | W11: 参数月
B12: =IFERROR(VLOOKUP(C12,'字段信息'!A:C,3,),"") | C12: company_code | D12: =IFERROR(VLOOKUP(C12,'字段信息'!A:C,2,),"") | F12: =B12 | G12: √ | L12: 普通级 | M12: 直接对应 | N12: Doris | O12: odsslt_s600_bsid odsslt_s600_bsad odsslt_s600_bsik odsslt_s600_bsak | P12: bukrs | V12: 直接对应 | W12: Doris | X12: ods.ods_slt_s600_faglflext ods.ods_slt_s700_faglflext ods.ods_slt_s800_glfunct ods.ods_slt_s810_faglflext（S610一起） ods.ods_slt_s900_glfunct | Y12: rbukrs
B13: =IFERROR(VLOOKUP(C13,'字段信息'!A:C,3,),"") | C13: acct_cert_type | D13: =IFERROR(VLOOKUP(C13,'字段信息'!A:C,2,),"") | F13: =B13 | G13: √ | L13: 普通级 | M13: 直接对应 | N13: Doris | O13: odsslt_s600_bsid odsslt_s600_bsad odsslt_s600_bsik odsslt_s600_bsak | P13: blart
B14: 凭证状态 | C14: acct_cert_status | D14: =IFERROR(VLOOKUP(C14,'字段信息'!A:C,2,),"") | F14: =B14 | G14: √ | M14: 直接对应 | N14: Doris | O14: odsslt_s600_bsid odsslt_s600_bsad odsslt_s600_bsik odsslt_s600_bsak | P14: bstat
B15: =IFERROR(VLOOKUP(C15,'字段信息'!A:C,3,),"") | C15: acct_cert_id | D15: =IFERROR(VLOOKUP(C15,'字段信息'!A:C,2,),"") | F15: =B15 | G15: √ | L15: 普通级 | M15: 直接对应 | N15: Doris | O15: odsslt_s600_bsid odsslt_s600_bsad odsslt_s600_bsik odsslt_s600_bsak | P15: belnr
B16: =IFERROR(VLOOKUP(C16,'字段信息'!A:C,3,),"") | C16: acct_cert_item | D16: =IFERROR(VLOOKUP(C16,'字段信息'!A:C,2,),"") | F16: =B16 | G16: √ | M16: 直接对应 | N16: Doris | O16: odsslt_s600_bsid odsslt_s600_bsad odsslt_s600_bsik odsslt_s600_bsak | P16: buzei
B17: =IFERROR(VLOOKUP(C17,'字段信息'!A:C,3,),"") | C17: voucher_dt | D17: =IFERROR(VLOOKUP(C17,'字段信息'!A:C,2,),"") | F17: =B17 | G17: √ | M17: 直接对应 | N17: Doris | O17: odsslt_s600_bsid odsslt_s600_bsad odsslt_s600_bsik odsslt_s600_bsak | P17: bldat
B18: =IFERROR(VLOOKUP(C18,'字段信息'!A:C,3,),"") | C18: posting_dt | D18: =IFERROR(VLOOKUP(C18,'字段信息'!A:C,2,),"") | F18: =B18 | G18: √ | L18: 普通级 | M18: 直接对应 | N18: Doris | O18: odsslt_s600_bsid odsslt_s600_bsad odsslt_s600_bsik odsslt_s600_bsak | P18: budat
B19: =IFERROR(VLOOKUP(C19,'字段信息'!A:C,3,),"") | C19: baseline_dt | D19: =IFERROR(VLOOKUP(C19,'字段信息'!A:C,2,),"") | F19: =B19 | G19: √ | L19: 普通级 | M19: 直接对应 | N19: Doris | O19: odsslt_s600_bsid odsslt_s600_bsad odsslt_s600_bsik odsslt_s600_bsak | P19: AB取ZFBDT，其他取BLDAT ZFBDT
B20: =IFERROR(VLOOKUP(C20,'字段信息'!A:C,3,),"") | C20: netrcp_dt | D20: =IFERROR(VLOOKUP(C20,'字段信息'!A:C,2,),"") | F20: =B20 | G20: √ | M20: 如果shkzg为S，根据基准日期+天数计算 如果为H，直接取基准日期 | N20: Doris | O20: odsslt_s600_bsid odsslt_s600_bsad odsslt_s600_bsik odsslt_s600_bsak | P20: ZFBDT + ZBD1T
B21: =IFERROR(VLOOKUP(C21,'字段信息'!A:C,3,),"") | C21: clearing_dt | D21: =IFERROR(VLOOKUP(C21,'字段信息'!A:C,2,),"") | F21: =B21 | G21: √ | L21: 普通级 | M21: 直接对应 | N21: Doris | O21: odsslt_s600_bsid odsslt_s600_bsad odsslt_s600_bsik odsslt_s600_bsak | P21: augdt
B22: =IFERROR(VLOOKUP(C22,'字段信息'!A:C,3,),"") | C22: cust_code | D22: =IFERROR(VLOOKUP(C22,'字段信息'!A:C,2,),"") | F22: =B22 | G22: √ | L22: 普通级 | M22: 直接对应 | N22: Doris | O22: odsslt_s600_bsid odsslt_s600_bsad odsslt_s600_bsik odsslt_s600_bsak | P22: 优先取分户编码，没有则取主户
B23: =IFERROR(VLOOKUP(C23,'字段信息'!A:C,3,),"") | C23: cust_name | D23: =IFERROR(VLOOKUP(C23,'字段信息'!A:C,2,),"") | F23: =B23 | G23: √ | L23: 普通级 | M23: odsslt_s600_bsid、odsslt_s600_bsad: 匹配客户主数据ods.odss600_kna1 odsslt_s600_bsik、odsslt_s600_bsak: 匹配供应商主数据ods.odss600_lfa1 | N23: Doris | O23: ods.odss600_kna1 ods.odss600_lfa1 | P23: 优先取分户名称，没有则取名称
B24: =IFERROR(VLOOKUP(C24,'字段信息'!A:C,3,),"") | C24: cust_head_code | D24: =IFERROR(VLOOKUP(C24,'字段信息'!A:C,2,),"") | F24: =B24 | G24: √ | L24: 普通级 | M24: 直接对应 | N24: Doris | O24: odsslt_s600_bsid odsslt_s600_bsad odsslt_s600_bsik odsslt_s600_bsak | P24: kunnr lifnr
B25: =IFERROR(VLOOKUP(C25,'字段信息'!A:C,3,),"") | C25: cust_head_name | D25: =IFERROR(VLOOKUP(C25,'字段信息'!A:C,2,),"") | F25: =B25 | G25: √ | L25: 普通级 | M25: odsslt_s600_bsid、odsslt_s600_bsad: 匹配客户主数据ods.odss600_kna1 odsslt_s600_bsik、odsslt_s600_bsak: 匹配供应商主数据ods.odss600_lfa1 | N25: Doris | O25: ods.odss600_kna1 ods.odss600_lfa1 | P25: name1 | Q25: 主户编码匹配客商主数据
B26: =IFERROR(VLOOKUP(C26,'字段信息'!A:C,3,),"") | C26: cust_branch_code | D26: =IFERROR(VLOOKUP(C26,'字段信息'!A:C,2,),"") | F26: =B26 | G26: √ | L26: 普通级 | M26: 直接对应 | N26: Doris | O26: odsslt_s600_bsid odsslt_s600_bsad odsslt_s600_bsik odsslt_s600_bsak | P26: filkd
B27: =IFERROR(VLOOKUP(C27,'字段信息'!A:C,3,),"") | C27: cust_branch_name | D27: =IFERROR(VLOOKUP(C27,'字段信息'!A:C,2,),"") | F27: =B27 | G27: √ | L27: 普通级 | M27: odsslt_s600_bsid、odsslt_s600_bsad: 匹配客户主数据ods.odss600_kna1 odsslt_s600_bsik、odsslt_s600_bsak: 匹配供应商主数据ods.odss600_lfa1 | N27: Doris | O27: ods.odss600_kna1 ods.odss600_lfa1 | P27: name1 | Q27: 分户编码匹配客商主数据
B28: =IFERROR(VLOOKUP(C28,'字段信息'!A:C,3,),"") | C28: cp_company_code | D28: =IFERROR(VLOOKUP(C28,'字段信息'!A:C,2,),"") | F28: =B28 | G28: √ | L28: 普通级 | M28: 匹配客商映射对方公司dim.dim_rule_fi_mr_cust2ctp_mapping | N28: Doris | O28: dim.dim_rule_fi_mr_cust2ctp_mapping | P28: 优先取cp_company_code_mr，为空则取cp_company_code | Q28: 主户编码匹配客商映射对方公司映射表
B29: =IFERROR(VLOOKUP(C29,'字段信息'!A:C,3,),"") | C29: country_code | D29: =IFERROR(VLOOKUP(C29,'字段信息'!A:C,2,),"") | F29: =B29 | G29: √ | L29: 普通级 | M29: 1、先匹配SAP客户主数据得到zkunnr_mdg 2、再匹配mdg客户主数据得到对应字段 | N29: Doris | O29: 1、ods.ods_slt_s600_kna1-客户主数据 2、dw.dim_customer_base_info_dd-客户主数据基本信息 | P29: 1、zkunnr_mdg 2、country_code | Q29: 1、kunnr = kunnr 2、zkunnr_mdg = cust_code
B30: =IFERROR(VLOOKUP(C30,'字段信息'!A:C,3,),"") | C30: country_name | D30: =IFERROR(VLOOKUP(C30,'字段信息'!A:C,2,),"") | F30: =B30 | G30: √ | M30: 1、先匹配SAP客户主数据得到zkunnr_mdg 2、再匹配mdg客户主数据得到对应字段 | N30: Doris | O30: 1、ods.ods_slt_s600_kna1-客户主数据 2、dw.dim_customer_base_info_dd-客户主数据基本信息 | P30: 1、zkunnr_mdg 2、country_name | Q30: 1、kunnr = kunnr 2、zkunnr_mdg = cust_code
B31: =IFERROR(VLOOKUP(C31,'字段信息'!A:C,3,),"") | C31: acct_type_code | D31: =IFERROR(VLOOKUP(C31,'字段信息'!A:C,2,),"") | F31: =B31 | G31: √ | L31: 普通级 | M31: 直接对应 | N31: Doris | O31: odsslt_s600_bsid odsslt_s600_bsad odsslt_s600_bsik odsslt_s600_bsak | P31: koart | V31: 直接对应 | W31: Doris | X31: ods.odss600_ztzt_003 | Y31: koart
B32: =IFERROR(VLOOKUP(C32,'字段信息'!A:C,3,),"") | C32: acct_src_code | D32: =IFERROR(VLOOKUP(C32,'字段信息'!A:C,2,),"") | F32: =B32 | G32: √ | L32: 普通级 | M32: 直接对应 | N32: Doris | O32: odsslt_s600_bsid odsslt_s600_bsad odsslt_s600_bsik odsslt_s600_bsak | P32: hkont | V32: 直接对应 | W32: Doris | X32: ods.ods_slt_s600_faglflext ods.ods_slt_s700_faglflext ods.ods_slt_s800_glfunct ods.ods_slt_s810_faglflext（S610一起） ods.ods_slt_s900_glfunct | Y32: racct
B33: =IFERROR(VLOOKUP(C33,'字段信息'!A:C,3,),"") | C33: acct_map_code | D33: =IFERROR(VLOOKUP(C33,'字段信息'!A:C,2,),"") | F33: =B33 | G33: √ | L33: 普通级 | M33: 匹配科目映射表dim.dim_rule_fi_mr_acct_mapping | N33: Doris | O33: dim.dim_rule_fi_mr_acct_mapping | P33: acct_map_code | Q33: 科目编码匹配科目映射表 | V33: 匹配科目映射表dim.dim_rule_fi_mr_acct_mapping | W33: Doris | X33: dim.dim_rule_fi_mr_acct_mapping | Y33: acct_map_code | Z33: 科目编码匹配科目映射表
A34: 0908：客户主数据匹配可以统一一个客户大表，通用逻辑匹配 | B34: =IFERROR(VLOOKUP(C34,'字段信息'!A:C,3,),"") | C34: channel_l1_code | D34: =IFERROR(VLOOKUP(C34,'字段信息'!A:C,2,),"") | F34: =B34 | G34: √ | L34: 普通级 | M34: 1、先匹配SAP客户主数据得到zkunnr_mdg 2、再匹配mdg客户主数据得到对应字段 | N34: Doris | O34: 1、ods.ods_slt_s600_kna1-客户主数据 2、dw.dim_customer_base_info_dd-客户主数据基本信息 | P34: 1、zkunnr_mdg 2、com_1st_code | Q34: 1、kunnr = kunnr 2、zkunnr_mdg = cust_code
B35: =IFERROR(VLOOKUP(C35,'字段信息'!A:C,3,),"") | C35: channel_l1_name | D35: =IFERROR(VLOOKUP(C35,'字段信息'!A:C,2,),"") | F35: =B35 | G35: √ | L35: 普通级 | M35: 1、先匹配SAP客户主数据得到zkunnr_mdg 2、再匹配mdg客户主数据得到对应字段 | N35: Doris | O35: 1、ods.ods_slt_s600_kna1-客户主数据 2、dw.dim_customer_base_info_dd-客户主数据基本信息 | P35: 1、zkunnr_mdg 2、com_1st_name | Q35: 1、kunnr = kunnr 2、zkunnr_mdg = cust_code
B36: =IFERROR(VLOOKUP(C36,'字段信息'!A:C,3,),"") | C36: channel_l2_code | D36: =IFERROR(VLOOKUP(C36,'字段信息'!A:C,2,),"") | F36: =B36 | G36: √ | L36: 普通级 | M36: 1、先匹配SAP客户主数据得到zkunnr_mdg 2、再匹配mdg客户主数据得到对应字段 | N36: Doris | O36: 1、ods.ods_slt_s600_kna1-客户主数据 2、dw.dim_customer_base_info_dd-客户主数据基本信息 | P36: 1、zkunnr_mdg 2、com_2nd_code | Q36: 1、kunnr = kunnr 2、zkunnr_mdg = cust_code
B37: =IFERROR(VLOOKUP(C37,'字段信息'!A:C,3,),"") | C37: channel_l2_name | D37: =IFERROR(VLOOKUP(C37,'字段信息'!A:C,2,),"") | F37: =B37 | G37: √ | L37: 普通级 | M37: 1、先匹配SAP客户主数据得到zkunnr_mdg 2、再匹配mdg客户主数据得到对应字段 | N37: Doris | O37: 1、ods.ods_slt_s600_kna1-客户主数据 2、dw.dim_customer_base_info_dd-客户主数据基本信息 | P37: 1、zkunnr_mdg 2、com_2nd_name | Q37: 1、kunnr = kunnr 2、zkunnr_mdg = cust_code
B38: =IFERROR(VLOOKUP(C38,'字段信息'!A:C,3,),"") | C38: channel_l3_code | D38: =IFERROR(VLOOKUP(C38,'字段信息'!A:C,2,),"") | F38: =B38 | G38: √ | L38: 普通级 | M38: 1、先匹配SAP客户主数据得到zkunnr_mdg 2、再匹配mdg客户主数据得到对应字段 | N38: Doris | O38: 1、ods.ods_slt_s600_kna1-客户主数据 2、dw.dim_customer_base_info_dd-客户主数据基本信息 | P38: 1、zkunnr_mdg 2、com_3rd_code | Q38: 1、kunnr = kunnr 2、zkunnr_mdg = cust_code
B39: =IFERROR(VLOOKUP(C39,'字段信息'!A:C,3,),"") | C39: channel_l3_name | D39: =IFERROR(VLOOKUP(C39,'字段信息'!A:C,2,),"") | F39: =B39 | G39: √ | L39: 普通级 | M39: 1、先匹配SAP客户主数据得到zkunnr_mdg 2、再匹配mdg客户主数据得到对应字段 | N39: Doris | O39: 1、ods.ods_slt_s600_kna1-客户主数据 2、dw.dim_customer_base_info_dd-客户主数据基本信息 | P39: 1、zkunnr_mdg 2、com_3rd_name | Q39: 1、kunnr = kunnr 2、zkunnr_mdg = cust_code
A40: 0908：等后续拉通后统一处理 | B40: =IFERROR(VLOOKUP(C40,'字段信息'!A:C,3,),"") | C40: tov_channel_code | D40: =IFERROR(VLOOKUP(C40,'字段信息'!A:C,2,),"") | F40: =B40 | G40: √ | M40: 待拉通后处理 | N40: Doris
...

Sheet dwd_fi_mr_ar_overdue_mi
A1: 返回 | B1: dwd_fi_mr_ar_odue_mi逻辑处理
A2: 规则库 | B2: 表名称 | C2: dwd.dwd_fi_mr_ar_overdue_mi
B3: 表描述 | C3: 超期款明细表 | D3: 表类型 | E3: 事实表 | F3: 数仓分层 | G3: DWD
B4: L1数仓目录 | C4: 管理财经 | D4: L2数仓目录 | E4: 财报管理 | F4: L3数仓目录 | G4: 应收
B5: 更新方式 | C5: 增量更新 | D5: 设计人员 | F5: 时间
B6: 使用场景 | C6: 取财务中台-问题资金系统中超期款及开票样机的金额 | M6: 待跟进事项： 1、问题资金系统需要新增公司+客商+利润中心字段--用户在提需求 | P6: 0908：超期款宽表应该包含调整数据，待文霞沟通 | V6: 待跟进事项： 1、问题资金系统需要新增公司+客商+利润中心字段--用户在提需求 2、问题资金给的后台表各字段筛选条件及匹配逻辑--待和问题资金的顾问沟通确认
B7: 目标表 | M7: 超期款dws.dws_fi_mr_wtzjcqkmx_mi | V7: 问题资金手工调整项【ods.odsfipf_tk_hfi_jtb_bjwtzjtz】
B8: 字段中文名称 | C8: *字段名称 | D8: *类型 | E8: 主键 | F8: *描述 | G8: 允许为空 | H8: 默认值 | I8: 聚合类型 | J8: 基础标准 | K8: 标准代码 | L8: *安全分级 | M8: 转换清洗规则 | N8: 源系统 | O8: 源头表 | P8: 源头字段 | Q8: 匹配字段 | R8: 匹配过滤 | S8: 数仓处理脚本 | T8: 备注 | V8: 转换清洗规则 | W8: 源系统 | X8: 源头表 | Y8: 源头字段 | Z8: 匹配字段 | AA8: 匹配过滤 | AB8: 数仓处理脚本 | AC8: 备注
B9: =IFERROR(VLOOKUP(C9,'字段信息'!A:C,3,),"") | C9: dt_month | D9: =IFERROR(VLOOKUP(C9,'字段信息'!A:C,2,),"") | F9: =B9 | M9: 直接对应 | N9: 参数年月 | O9: dws.dws_fi_mr_wtzjcqkmx_mi | P9: start_dt | V9: 截取字段对应年月 限制条件： fstatus = 'E' and fk_hifi_mk = '4' | W9: 参数年月 | X9: ods.odsfipf_tk_hfi_jtb_bjtwtzjtz | Y9: fk_hifi_tzyf
B10: =IFERROR(VLOOKUP(C10,'字段信息'!A:C,3,),"") | C10: year | D10: =IFERROR(VLOOKUP(C10,'字段信息'!A:C,2,),"") | F10: =B10 | G10: √ | M10: 直接对应 | N10: 参数年 | O10: dws.dws_fi_mr_wtzjcqkmx_mi | P10: start_dt截取年份 | V10: 截取字段对应年份 | W10: 参数年 | X10: ods.odsfipf_tk_hfi_jtb_bjtwtzjtz | Y10: fk_hifi_tzyf
B11: =IFERROR(VLOOKUP(C11,'字段信息'!A:C,3,),"") | C11: month | D11: =IFERROR(VLOOKUP(C11,'字段信息'!A:C,2,),"") | F11: =B11 | G11: √ | L11: 普通级 | M11: 直接对应 | N11: 参数月 | O11: dws.dws_fi_mr_wtzjcqkmx_mi | P11: start_dt截取月份 | V11: 截取字段对应月份 | W11: 参数月 | X11: ods.odsfipf_tk_hfi_jtb_bjtwtzjtz | Y11: fk_hifi_tzyf
B12: =IFERROR(VLOOKUP(C12,'字段信息'!A:C,3,),"") | C12: company_code | D12: =IFERROR(VLOOKUP(C12,'字段信息'!A:C,2,),"") | F12: =B12 | G12: √ | L12: 普通级 | M12: 直接对应 | N12: Doris | O12: dws.dws_fi_mr_wtzjcqkmx_mi | P12: ledge_code | V12: 根据公司名称判断 平板电视： 冰箱公司（冰冷）： 空调公司： 海信日立： 营销服中心——内销： | W12: Doris | X12: ods.odsfipf_tk_hfi_jtb_bjtwtzjtz | Y12: fk_hifi_gs
B13: =IFERROR(VLOOKUP(C13,'字段信息'!A:C,3,),"") | C13: acct_src_code | D13: =IFERROR(VLOOKUP(C13,'字段信息'!A:C,2,),"") | F13: =B13 | G13: √ | L13: 普通级 | M13: 直接对应 | N13: Doris | O13: dws.dws_fi_mr_wtzjcqkmx_mi | P13: gl_account | V13: 1122000000
B14: =IFERROR(VLOOKUP(C14,'字段信息'!A:C,3,),"") | C14: cust_code | D14: =IFERROR(VLOOKUP(C14,'字段信息'!A:C,2,),"") | F14: =B14 | G14: √ | L14: 普通级 | M14: 直接对应 | N14: Doris | O14: dws.dws_fi_mr_wtzjcqkmx_mi | P14: cust_code
B15: =IFERROR(VLOOKUP(C15,'字段信息'!A:C,3,),"") | C15: cust_name | D15: =IFERROR(VLOOKUP(C15,'字段信息'!A:C,2,),"") | F15: =B15 | G15: √ | L15: 普通级 | M15: 直接对应 | N15: Doris | O15: dws.dws_fi_mr_wtzjcqkmx_mi | P15: cust_name
B16: =IFERROR(VLOOKUP(C16,'字段信息'!A:C,3,),"") | C16: cp_company_code | D16: =IFERROR(VLOOKUP(C16,'字段信息'!A:C,2,),"") | F16: =B16 | G16: √ | M16: 匹配客商映射对方公司dim.dim_rule_fi_mr_cust2ctp_mapping | N16: Doris | O16: dim.dim_rule_fi_mr_cust2ctp_mapping | P16: 优先取cp_company_code_mr，为空则取cp_company_code | Q16: 客商编码匹配客商映射对方公司映射表
B17: =IFERROR(VLOOKUP(C17,'字段信息'!A:C,3,),"") | C17: country_code | D17: =IFERROR(VLOOKUP(C17,'字段信息'!A:C,2,),"") | F17: =B17 | G17: √ | M17: 直接对应 | N17: Doris | O17: dws.dws_fi_mr_wtzjcqkmx_mi | P17: country_code
B18: =IFERROR(VLOOKUP(C18,'字段信息'!A:C,3,),"") | C18: country_name | D18: =IFERROR(VLOOKUP(C18,'字段信息'!A:C,2,),"") | F18: =B18 | G18: √ | M18: 直接对应 | N18: Doris | O18: dws.dws_fi_mr_wtzjcqkmx_mi | P18: country_name
B19: =IFERROR(VLOOKUP(C19,'字段信息'!A:C,3,),"") | C19: channel_l1_code | D19: =IFERROR(VLOOKUP(C19,'字段信息'!A:C,2,),"") | F19: =B19 | G19: √ | M19: 直接对应 | N19: Doris | O19: dws.dws_fi_mr_wtzjcqkmx_mi | P19: comp_cls_l1
B20: =IFERROR(VLOOKUP(C20,'字段信息'!A:C,3,),"") | C20: channel_l1_name | D20: =IFERROR(VLOOKUP(C20,'字段信息'!A:C,2,),"") | F20: =B20 | G20: √ | N20: Doris
B21: =IFERROR(VLOOKUP(C21,'字段信息'!A:C,3,),"") | C21: channel_l2_code | D21: =IFERROR(VLOOKUP(C21,'字段信息'!A:C,2,),"") | F21: =B21 | G21: √ | M21: 直接对应 | N21: Doris | O21: dws.dws_fi_mr_wtzjcqkmx_mi | P21: comp_cls_l2
B22: =IFERROR(VLOOKUP(C22,'字段信息'!A:C,3,),"") | C22: channel_l2_name | D22: =IFERROR(VLOOKUP(C22,'字段信息'!A:C,2,),"") | F22: =B22 | G22: √ | N22: Doris
B23: =IFERROR(VLOOKUP(C23,'字段信息'!A:C,3,),"") | C23: channel_l3_code | D23: =IFERROR(VLOOKUP(C23,'字段信息'!A:C,2,),"") | F23: =B23 | G23: √ | M23: 直接对应 | N23: Doris | O23: dws.dws_fi_mr_wtzjcqkmx_mi | P23: comp_cls_l3
B24: =IFERROR(VLOOKUP(C24,'字段信息'!A:C,3,),"") | C24: channel_l3_name | D24: =IFERROR(VLOOKUP(C24,'字段信息'!A:C,2,),"") | F24: =B24 | G24: √ | N24: Doris
B25: =IFERROR(VLOOKUP(C25,'字段信息'!A:C,3,),"") | C25: onoffline_code | D25: =IFERROR(VLOOKUP(C25,'字段信息'!A:C,2,),"") | F25: =B25 | G25: √ | M25: 直接对应 | N25: Doris | O25: dws.dws_fi_mr_wtzjcqkmx_mi | P25: channel_group
B26: =IFERROR(VLOOKUP(C26,'字段信息'!A:C,3,),"") | C26: onoffline_name | D26: =IFERROR(VLOOKUP(C26,'字段信息'!A:C,2,),"") | F26: =B26 | G26: √
B27: =IFERROR(VLOOKUP(C27,'字段信息'!A:C,3,),"") | C27: src_profitcenter_code | D27: =IFERROR(VLOOKUP(C27,'字段信息'!A:C,2,),"") | F27: =B27 | G27: √ | L27: 普通级 | M27: 直接对应 | N27: Doris | O27: dws.dws_fi_mr_wtzjcqkmx_mi | P27: profit_center_code
B28: =IFERROR(VLOOKUP(C28,'字段信息'!A:C,3,),"") | C28: src_profitcenter_name | D28: =IFERROR(VLOOKUP(C28,'字段信息'!A:C,2,),"") | F28: =B28 | G28: √ | L28: 普通级 | M28: 直接对应 | N28: Doris | O28: dws.dws_fi_mr_wtzjcqkmx_mi | P28: profit_center_name
B29: =IFERROR(VLOOKUP(C29,'字段信息'!A:C,3,),"") | C29: profitcenter_code | D29: =IFERROR(VLOOKUP(C29,'字段信息'!A:C,2,),"") | F29: =B29 | G29: √ | L29: 普通级 | M29: 直接对应 | N29: Doris | O29: dws.dws_fi_mr_wtzjcqkmx_mi | P29: profit_center_code
B30: =IFERROR(VLOOKUP(C30,'字段信息'!A:C,3,),"") | C30: profitcenter_name | D30: =IFERROR(VLOOKUP(C30,'字段信息'!A:C,2,),"") | F30: =B30 | G30: √ | L30: 普通级 | M30: 直接对应 | N30: Doris | O30: dws.dws_fi_mr_wtzjcqkmx_mi | P30: profit_center_name
B31: =IFERROR(VLOOKUP(C31,'字段信息'!A:C,3,),"") | C31: bus_range_code | D31: =IFERROR(VLOOKUP(C31,'字段信息'!A:C,2,),"") | F31: =B31 | G31: √ | M31: 直接对应 | N31: Doris | O31: dws.dws_fi_mr_wtzjcqkmx_mi | P31: bus_scope_code
B32: =IFERROR(VLOOKUP(C32,'字段信息'!A:C,3,),"") | C32: bus_range_name | D32: =IFERROR(VLOOKUP(C32,'字段信息'!A:C,2,),"") | F32: =B32 | G32: √ | M32: 直接对应 | N32: Doris | O32: dws.dws_fi_mr_wtzjcqkmx_mi | P32: bus_scope_desc
B33: =IFERROR(VLOOKUP(C33,'字段信息'!A:C,3,),"") | C33: marketing_dept_code | D33: =IFERROR(VLOOKUP(C33,'字段信息'!A:C,2,),"") | F33: =B33 | G33: √ | M33: 直接对应 | N33: Doris | O33: dws.dws_fi_mr_wtzjcqkmx_mi | P33: biz_mgmt_unit
B34: =IFERROR(VLOOKUP(C34,'字段信息'!A:C,3,),"") | C34: marketing_dept_name | D34: =IFERROR(VLOOKUP(C34,'字段信息'!A:C,2,),"") | F34: =B34 | G34: √
B35: =IFERROR(VLOOKUP(C35,'字段信息'!A:C,3,),"") | C35: bcy_code | D35: =IFERROR(VLOOKUP(C35,'字段信息'!A:C,2,),"") | F35: =B35 | G35: √ | V35: CNY
B36: =IFERROR(VLOOKUP(C36,'字段信息'!A:C,3,),"") | C36: qcy_code | D36: =IFERROR(VLOOKUP(C36,'字段信息'!A:C,2,),"") | F36: =B36 | G36: √ | V36: CNY
B37: =IFERROR(VLOOKUP(C37,'字段信息'!A:C,3,),"") | C37: overdue_1_amt | D37: =IFERROR(VLOOKUP(C37,'字段信息'!A:C,2,),"") | F37: =B37 | G37: √
B38: =IFERROR(VLOOKUP(C38,'字段信息'!A:C,3,),"") | C38: overdue_2_amt | D38: =IFERROR(VLOOKUP(C38,'字段信息'!A:C,2,),"") | F38: =B38 | G38: √
B39: =IFERROR(VLOOKUP(C39,'字段信息'!A:C,3,),"") | C39: overdue_3_amt | D39: =IFERROR(VLOOKUP(C39,'字段信息'!A:C,2,),"") | F39: =B39 | G39: √
B40: =IFERROR(VLOOKUP(C40,'字段信息'!A:C,3,),"") | C40: overdue_4_amt | D40: =IFERROR(VLOOKUP(C40,'字段信息'!A:C,2,),"") | F40: =B40 | G40: √
...

Sheet dwd_fi_mr_ar_ureb_mi
A1: 返回 | B1: dwd_fi_mr_ar_ureb_mi逻辑处理
A2: 规则库 | B2: 表名称 | C2: dwd.dwd_fi_mr_ar_ureb_mi
B3: 表描述 | C3: 欠付返利明细表 | D3: 表类型 | E3: 事实表 | F3: 数仓分层 | G3: DWD
B4: L1数仓目录 | C4: 管理财经 | D4: L2数仓目录 | E4: 财报管理 | F4: L3数仓目录 | G4: 收入
B5: 更新方式 | C5: 增量更新 | D5: 设计人员 | F5: 时间 | M5: 待确认：1、数据更新机制；2、不到利润中心怎么匹配--日立的往来数据不到利润中心
B6: 使用场景 | C6: 取SMS系统、政策系统、SAP系统的欠付返利明细 | M6: 0908：前面要再加一个静态存数的表，和用户沟通风险点，最好是前端系统存静态数据
B7: 目标表 | M7: SMS经销商返利余额汇总管理表 | V7: 已确认未兑现政策余额数据 | AE7: SAP客户行项目明细
B8: 字段中文名称 | C8: *字段名称 | D8: *类型 | E8: 主键 | F8: *描述 | G8: 允许为空 | H8: 默认值 | I8: 聚合类型 | J8: 基础标准 | K8: 标准代码 | L8: *安全分级 | M8: 转换清洗规则 | N8: 源系统 | O8: 源头表 | P8: 源头字段 | Q8: 匹配字段 | R8: 匹配过滤 | S8: 数仓处理脚本 | T8: 备注 | V8: 转换清洗规则 | W8: 源系统 | X8: 源头表 | Y8: 源头字段 | Z8: 匹配字段 | AA8: 匹配过滤 | AB8: 数仓处理脚本 | AC8: 备注 | AE8: 转换清洗规则 | AF8: 源系统 | AG8: 源头表 | AH8: 源头字段 | AI8: 匹配字段 | AJ8: 匹配过滤 | AK8: 数仓处理脚本 | AL8: 备注
B9: =IFERROR(VLOOKUP(C9,'字段信息'!A:C,3,),"") | C9: dt_month | D9: =IFERROR(VLOOKUP(C9,'字段信息'!A:C,2,),"") | F9: =B9 | M9: 参数年月 | V9: 参数年月 | W9: Doris | X9: ods.ods_plc_v_hpms_account_gb | Y9: period | AE9: 参数年月 | AG9: dwd_fi_mr_arap_detail_mi | AH9: dt_month
B10: =IFERROR(VLOOKUP(C10,'字段信息'!A:C,3,),"") | C10: year | D10: =IFERROR(VLOOKUP(C10,'字段信息'!A:C,2,),"") | F10: =B10 | G10: √ | L10: 普通级 | M10: 参数年 | N10: Doris | V10: 参数年 | W10: Doris | X10: ods.ods_plc_v_hpms_account_gb | Y10: LEFT(period,4) | AE10: 参数年 | AF10: Doris | AG10: dwd_fi_mr_arap_detail_mi | AH10: year
B11: =IFERROR(VLOOKUP(C11,'字段信息'!A:C,3,),"") | C11: month | D11: =IFERROR(VLOOKUP(C11,'字段信息'!A:C,2,),"") | F11: =B11 | G11: √ | L11: 普通级 | M11: 参数月 | N11: Doris | V11: 参数月 | W11: Doris | X11: ods.ods_plc_v_hpms_account_gb | Y11: RIGHT(period,2) | AE11: 参数月 | AF11: Doris | AG11: dwd_fi_mr_arap_detail_mi | AH11: month
B12: =IFERROR(VLOOKUP(C12,'字段信息'!A:C,3,),"") | C12: company_code | D12: =IFERROR(VLOOKUP(C12,'字段信息'!A:C,2,),"") | F12: =B12 | G12: √ | L12: 普通级 | M12: 直接对应 | N12: Doris | O12: dwd_ltc_cem_reportpay_balance_summary_dd | P12: company_code | V12: 直接对应 | W12: Doris | X12: ods.ods_plc_v_hpms_account_gb | Y12: sales_group | AE12: 直接对应 | AF12: Doris | AG12: dwd_fi_mr_arap_detail_mi | AH12: company_code
B13: 客商编码 | C13: cust_code | D13: =IFERROR(VLOOKUP(C13,'字段信息'!A:C,2,),"") | F13: =B13 | G13: √ | L13: 普通级 | M13: 直接对应 | N13: Doris | O13: dwd_ltc_cem_reportpay_balance_summary_dd | P13: sales_code | V13: 直接对应 | W13: Doris | X13: ods.ods_plc_v_hpms_account_gb | Y13: customer_code | AE13: 直接对应 | AF13: Doris | AG13: dwd_fi_mr_arap_detail_mi | AH13: customer_code
B14: 客商名称 | C14: cust_name | D14: =IFERROR(VLOOKUP(C14,'字段信息'!A:C,2,),"") | F14: =B14 | G14: √ | L14: 普通级 | M14: 直接对应 | N14: Doris | O14: dwd_ltc_cem_reportpay_balance_summary_dd | P14: sname | V14: 直接对应 | W14: Doris | X14: ods.ods_plc_v_hpms_account_gb | Y14: customer_name | AE14: 直接对应 | AF14: Doris | AG14: dwd_fi_mr_arap_detail_mi | AH14: customer_name
B15: =IFERROR(VLOOKUP(C15,'字段信息'!A:C,3,),"") | C15: cp_company_code | D15: =IFERROR(VLOOKUP(C15,'字段信息'!A:C,2,),"") | F15: =B15 | G15: √ | M15: 匹配客商映射对方公司dim.dim_rule_fi_mr_cust2ctp_mapping | N15: Doris | O15: dim.dim_rule_fi_mr_cust2ctp_mapping | P15: 优先取cp_company_code_mr，为空则取cp_company_code | Q15: 客商编码匹配客商映射对方公司映射表 | V15: 匹配客商映射对方公司dim.dim_rule_fi_mr_cust2ctp_mapping | W15: Doris | X15: dim.dim_rule_fi_mr_cust2ctp_mapping | Y15: 优先取cp_company_code_mr，为空则取cp_company_code | Z15: 客商编码匹配客商映射对方公司映射表 | AE15: 直接对应 | AF15: Doris | AG15: dwd_fi_mr_arap_detail_mi | AH15: cp_company_code
B16: =IFERROR(VLOOKUP(C16,'字段信息'!A:C,3,),"") | C16: country_code | D16: =IFERROR(VLOOKUP(C16,'字段信息'!A:C,2,),"") | F16: =B16 | G16: √ | M16: 匹配mdg客户主数据得到对应字段 | N16: Doris | O16: dw.dim_customer_base_info_dd-客户主数据基本信息 | P16: country_code | Q16: kunnr_mdg = cust_code | V16: 匹配mdg客户主数据得到对应字段 | W16: Doris | X16: dw.dim_customer_base_info_dd-客户主数据基本信息 | Y16: country_code | Z16: kunnr_mdg = cust_code | AE16: 直接对应 | AF16: Doris | AG16: dwd_fi_mr_arap_detail_mi | AH16: country_code
B17: =IFERROR(VLOOKUP(C17,'字段信息'!A:C,3,),"") | C17: country_name | D17: =IFERROR(VLOOKUP(C17,'字段信息'!A:C,2,),"") | F17: =B17 | G17: √ | M17: 匹配mdg客户主数据得到对应字段 | N17: Doris | O17: dw.dim_customer_base_info_dd-客户主数据基本信息 | P17: country_code | Q17: kunnr_mdg = cust_code | V17: 匹配mdg客户主数据得到对应字段 | W17: Doris | X17: dw.dim_customer_base_info_dd-客户主数据基本信息 | Y17: country_code | Z17: kunnr_mdg = cust_code | AE17: 直接对应 | AF17: Doris | AG17: dwd_fi_mr_arap_detail_mi | AH17: country_code
B18: =IFERROR(VLOOKUP(C18,'字段信息'!A:C,3,),"") | C18: src_profitcenter_code | D18: =IFERROR(VLOOKUP(C18,'字段信息'!A:C,2,),"") | F18: =B18 | G18: √ | L18: 普通级 | M18: / | V18: 直接对应 | W18: Doris | X18: ods.ods_plc_v_hpms_account_gb | Y18: profit_center | AE18: 直接对应 | AF18: Doris | AG18: dwd_fi_mr_arap_detail_mi | AH18: src_profitcenter_code
B19: =IFERROR(VLOOKUP(C19,'字段信息'!A:C,3,),"") | C19: src_profitcenter_name | D19: =IFERROR(VLOOKUP(C19,'字段信息'!A:C,2,),"") | F19: =B19 | G19: √ | L19: 普通级 | M19: / | V19: / | AE19: 直接对应 | AF19: Doris | AG19: dwd_fi_mr_arap_detail_mi | AH19: src_profitcenter_name
B20: =IFERROR(VLOOKUP(C20,'字段信息'!A:C,3,),"") | C20: profitcenter_code | D20: =IFERROR(VLOOKUP(C20,'字段信息'!A:C,2,),"") | F20: =B20 | G20: √ | M20: / | V20: 匹配《应收模块-利润中心映射表》，筛选映射类型为“收入利润中心映射往来利润中心”，将收入利润中心映射成应收利润中心 | W20: Doris | X20: dim_rule_fi_mr_ar_prctr_map经分项目应收模块-利润中心映射表 | AE20: 直接对应 | AF20: Doris | AG20: dwd_fi_mr_arap_detail_mi | AH20: profitcenter_code
B21: =IFERROR(VLOOKUP(C21,'字段信息'!A:C,3,),"") | C21: profitcenter_name | D21: =IFERROR(VLOOKUP(C21,'字段信息'!A:C,2,),"") | F21: =B21 | G21: √ | M21: / | V21: 匹配《应收模块-利润中心映射表》，筛选映射类型为“收入利润中心映射往来利润中心”，将收入利润中心映射成应收利润中心 | W21: Doris | X21: dim_rule_fi_mr_ar_prctr_map经分项目应收模块-利润中心映射表 | AE21: 直接对应 | AF21: Doris | AG21: dwd_fi_mr_arap_detail_mi | AH21: profitcenter_name
B22: =IFERROR(VLOOKUP(C22,'字段信息'!A:C,3,),"") | C22: reb_type | D22: =IFERROR(VLOOKUP(C22,'字段信息'!A:C,2,),"") | F22: =B22 | G22: √ | M22: 直接对应 | N22: Doris | O22: dwd_ltc_cem_reportpay_balance_summary_dd | P22: leibie | V22: 直接对应 | W22: Doris | AE22: / | AF22: Doris
B23: =IFERROR(VLOOKUP(C23,'字段信息'!A:C,3,),"") | C23: ledger_status | D23: =IFERROR(VLOOKUP(C23,'字段信息'!A:C,2,),"") | F23: =B23 | G23: √ | M23: / | N23: Doris | V23: 直接对应 | W23: Doris | X23: ods.ods_plc_v_hpms_account_gb | Y23: policystatename | AA23: 已确认未兑现：兑现过程中、确认完成 已计提未兑现：待确认 | AE23: / | AF23: Doris
B24: =IFERROR(VLOOKUP(C24,'字段信息'!A:C,3,),"") | C24: acct_cert_type | D24: =IFERROR(VLOOKUP(C24,'字段信息'!A:C,2,),"") | F24: =B24 | G24: √ | M24: / | V24: / | AE24: 直接对应 | AF24: Doris | AG24: dwd_fi_mr_arap_detail_mi | AH24: acct_cert_type | AJ24: zz
B25: =IFERROR(VLOOKUP(C25,'字段信息'!A:C,3,),"") | C25: pay_reason_code | D25: =IFERROR(VLOOKUP(C25,'字段信息'!A:C,2,),"") | F25: =B25 | G25: √ | M25: / | V25: / | AE25: 直接对应 | AF25: Doris | AG25: dwd_fi_mr_arap_detail_mi | AH25: pay_reason_code | AJ25: 600 | AK25: 0908：从凭证明细表中取，根据打的标签来判断
B26: =IFERROR(VLOOKUP(C26,'字段信息'!A:C,3,),"") | C26: bcy_code | D26: =IFERROR(VLOOKUP(C26,'字段信息'!A:C,2,),"") | F26: =B26 | G26: √ | L26: 普通级 | M26: 固定CNY | N26: Doris | O26: CNY | V26: 固定CNY | W26: Doris | X26: ods.ods_plc_v_hpms_account_gb | Y26: CNY | AE26: 直接对应 | AF26: Doris | AG26: dwd_fi_mr_arap_detail_mi | AH26: bcy_code | AJ26: 筛选ods_src为bsid且acct_map_code为1122%
B27: =IFERROR(VLOOKUP(C27,'字段信息'!A:C,3,),"") | C27: qcy_code | D27: =IFERROR(VLOOKUP(C27,'字段信息'!A:C,2,),"") | F27: =B27 | G27: √ | L27: 普通级 | M27: 固定CNY | N27: Doris | O27: CNY | V27: 固定CNY | W27: Doris | X27: ods.ods_plc_v_hpms_account_gb | Y27: CNY | AE27: 直接对应 | AF27: Doris | AG27: dwd_fi_mr_arap_detail_mi | AH27: qcy_code
B28: =IFERROR(VLOOKUP(C28,'字段信息'!A:C,3,),"") | C28: bcy_amt | D28: =IFERROR(VLOOKUP(C28,'字段信息'!A:C,2,),"") | F28: =B28 | G28: √ | L28: 普通级 | M28: 直接对应 | N28: Doris | O28: dwd_ltc_cem_reportpay_balance_summary_dd | P28: yue | V28: 直接对应 | W28: Doris | X28: ods.ods_plc_v_hpms_account_gb | Y28: arrears_amount | AE28: 直接对应 | AF28: Doris | AG28: dwd_fi_mr_arap_detail_mi | AH28: bcy_amt
B29: =IFERROR(VLOOKUP(C29,'字段信息'!A:C,3,),"") | C29: qcy_amt | D29: =IFERROR(VLOOKUP(C29,'字段信息'!A:C,2,),"") | F29: =B29 | G29: √ | L29: 普通级 | M29: 直接对应 | N29: Doris | O29: dwd_ltc_cem_reportpay_balance_summary_dd | P29: yue | V29: 直接对应 | W29: Doris | X29: ods.ods_plc_v_hpms_account_gb | Y29: arrears_amount | AE29: 直接对应 | AF29: Doris | AG29: dwd_fi_mr_arap_detail_mi | AH29: qcy_amt
B30: =IFERROR(VLOOKUP(C30,'字段信息'!A:C,3,),"") | C30: ods_src | D30: =IFERROR(VLOOKUP(C30,'字段信息'!A:C,2,),"") | F30: =B30 | G30: √ | L30: 普通级 | M30: 固定值 | N30: Doris | P30: SMS | V30: 固定值 | W30: Doris | Y30: policy | AE30: 固定值 | AF30: Doris | AK30: SAP
B31: =IFERROR(VLOOKUP(C31,'字段信息'!A:C,3,),"") | C31: load_dt | D31: =IFERROR(VLOOKUP(C31,'字段信息'!A:C,2,),"") | F31: =B31 | G31: √ | L31: 普通级 | M31: 数据更新时间 | N31: Doris | V31: 数据更新时间 | W31: Doris | AE31: 数据更新时间 | AF31: Doris

Sheet dwd_fi_mr_ar_imocc_mi
A1: 返回 | B1: dwd_fi_mr_ar_imocc_mi逻辑处理
A2: 规则库 | B2: 表名称 | C2: dwd.dwd_fi_mr_ar_imocc_mi
B3: 表描述 | C3: 国际营销应收占用明细表 | D3: 表类型 | E3: 事实表 | F3: 数仓分层 | G3: DWD
B4: L1数仓目录 | C4: 管理财经 | D4: L2数仓目录 | E4: 财报管理 | F4: L3数仓目录 | G4: 应收
B5: 更新方式 | C5: 增量更新 | D5: 设计人员 | F5: 时间
B6: 使用场景 | C6: 取信数系统中国际营销对外的的应收占用数据
B7: 目标表 | M7: 国际营销占用ads.ads_fi_mr_accounts_rec_di
B8: 字段中文名称 | C8: *字段名称 | D8: *类型 | E8: 主键 | F8: *描述 | G8: 允许为空 | H8: 默认值 | I8: 聚合类型 | J8: 基础标准 | K8: 标准代码 | L8: *安全分级 | M8: 转换清洗规则 | N8: 源系统 | O8: 源头表 | P8: 源头字段 | Q8: 匹配字段 | R8: 匹配过滤 | S8: 数仓处理脚本 | T8: 备注
B9: =IFERROR(VLOOKUP(C9,'字段信息'!A:C,3,),"") | C9: dt_month | D9: =IFERROR(VLOOKUP(C9,'字段信息'!A:C,2,),"") | F9: =B9 | M9: 直接对应 | N9: 参数年月 | O9: ads.ads_fi_mr_accounts_rec_di | P9: month_dt
B10: =IFERROR(VLOOKUP(C10,'字段信息'!A:C,3,),"") | C10: year | D10: =IFERROR(VLOOKUP(C10,'字段信息'!A:C,2,),"") | F10: =B10 | G10: √ | M10: 直接对应 | N10: 参数年 | O10: ads.ads_fi_mr_accounts_rec_di | P10: month_dt截取年份
B11: =IFERROR(VLOOKUP(C11,'字段信息'!A:C,3,),"") | C11: month | D11: =IFERROR(VLOOKUP(C11,'字段信息'!A:C,2,),"") | F11: =B11 | G11: √ | L11: 普通级 | M11: 直接对应 | N11: 参数月 | O11: ads.ads_fi_mr_accounts_rec_di | P11: month_dt截取月份
B12: =IFERROR(VLOOKUP(C12,'字段信息'!A:C,3,),"") | C12: company_src_code | D12: =IFERROR(VLOOKUP(C12,'字段信息'!A:C,2,),"") | F12: =B12 | G12: √ | L12: 普通级 | M12: 直接对应 | N12: Doris | O12: ads.ads_fi_mr_accounts_rec_di | P12: bukrs
B13: =IFERROR(VLOOKUP(C13,'字段信息'!A:C,3,),"") | C13: company_code | D13: =IFERROR(VLOOKUP(C13,'字段信息'!A:C,2,),"") | F13: =B13 | G13: √ | M13: 根据条件判断 1、商显公司2080： 取product_line_code=01A0 OR region_flag为‘B2B业务拓展部’的数据 2、日立公司1740： region_flag为‘产品线大区’ AND product_line_code=0207 其余默认放8010
B14: =IFERROR(VLOOKUP(C14,'字段信息'!A:C,3,),"") | C14: region_code | D14: =IFERROR(VLOOKUP(C14,'字段信息'!A:C,2,),"") | F14: =B14 | G14: √ | M14: 直接对应 | N14: Doris | O14: ads.ads_fi_mr_accounts_rec_di | P14: rgn
B15: =IFERROR(VLOOKUP(C15,'字段信息'!A:C,3,),"") | C15: region_name | D15: =IFERROR(VLOOKUP(C15,'字段信息'!A:C,2,),"") | F15: =B15 | G15: √ | M15: 匹配区组主数据 | N15: Doris | O15: ads.ads_fi_mr_accounts_rec_didw.dwsd_im_td_bdr_area_group a2--区组主数据 | P15: rgn_zh
B16: =IFERROR(VLOOKUP(C16,'字段信息'!A:C,3,),"") | C16: region_flag | D16: =IFERROR(VLOOKUP(C16,'字段信息'!A:C,2,),"") | F16: =B16 | G16: √ | M16: 匹配区组主数据和产品线主数据进行判断 | N16: Doris | O16: ads.ads_fi_mr_accounts_rec_di dw.dwsd_im_td_bdr_area_group a2--区组主数据 dw.dwfi_im_td_product_category a3--产品线主数据 | P16: case when A1.month_dt>='202504' AND (A3.prdln in ('0207','0403','0401','0402') OR (A3.prdln='01A0' AND A2.grp<>'D0090')) then '产品线大区' when A1.month_dt<'202504' AND A3.prdln in ('0207','01A0','0403','0401','0402') then '产品线大区' when (A2.rgn_zh is null and A3.prdln not in ('0207','01A0','0403','0401','0402')) or A1.type ='8002' then '欧洲区' else A2.rgn_zh end | Q16: a1.grp=a2.grp a1.prdln=a3.prdln | R16: 产品线主数据需要现在enable_flag='T'
B17: =IFERROR(VLOOKUP(C17,'字段信息'!A:C,3,),"") | C17: area_group_code | D17: =IFERROR(VLOOKUP(C17,'字段信息'!A:C,2,),"") | F17: =B17 | G17: √ | M17: 直接对应 | N17: Doris | O17: ads.ads_fi_mr_accounts_rec_di | P17: grp
B18: =IFERROR(VLOOKUP(C18,'字段信息'!A:C,3,),"") | C18: area_group_name | D18: =IFERROR(VLOOKUP(C18,'字段信息'!A:C,2,),"") | F18: =B18 | G18: √ | M18: 匹配区组主数据 | N18: Doris | O18: ads.ads_fi_mr_accounts_rec_di dw.dwsd_im_td_bdr_area_group a2--区组主数据 | P18: grp_zh
B19: =IFERROR(VLOOKUP(C19,'字段信息'!A:C,3,),"") | C19: area_group_flag | D19: =IFERROR(VLOOKUP(C19,'字段信息'!A:C,2,),"") | F19: =B19 | G19: √ | M19: 匹配区组主数据 | N19: Doris | O19: ads.ads_fi_mr_accounts_rec_di dw.dwsd_im_td_bdr_area_group a2--区组主数据 | P19: case when A1.type ='8002' then '欧洲海外' else A2.grp_zh end | Q19: a1.grp=a2.grp
B20: =IFERROR(VLOOKUP(C20,'字段信息'!A:C,3,),"") | C20: bus_model_code | D20: =IFERROR(VLOOKUP(C20,'字段信息'!A:C,2,),"") | F20: =B20 | G20: √ | M20: 直接对应 | N20: Doris | O20: ads.ads_fi_mr_accounts_rec_di | P20: bus_model
B21: =IFERROR(VLOOKUP(C21,'字段信息'!A:C,3,),"") | C21: product_big_class_code | D21: =IFERROR(VLOOKUP(C21,'字段信息'!A:C,2,),"") | F21: =B21 | G21: √ | M21: 直接对应 | N21: Doris | O21: ads.ads_fi_mr_accounts_rec_di | P21: prdctgy
B22: =IFERROR(VLOOKUP(C22,'字段信息'!A:C,3,),"") | C22: product_big_class_name | D22: =IFERROR(VLOOKUP(C22,'字段信息'!A:C,2,),"") | F22: =B22 | G22: √ | M22: 匹配产品线主数据进行判断 | N22: Doris | O22: ads.ads_fi_mr_accounts_rec_di dw.dwfi_im_td_product_category a3--产品线主数据 | P22: prdctgy_zh | Q22: a1.prdln=a3.prdln | R22: 产品线主数据需要现在enable_flag='T'
B23: =IFERROR(VLOOKUP(C23,'字段信息'!A:C,3,),"") | C23: product_line_code | D23: =IFERROR(VLOOKUP(C23,'字段信息'!A:C,2,),"") | F23: =B23 | G23: √ | M23: 直接对应 | N23: Doris | O23: ads.ads_fi_mr_accounts_rec_di | P23: prdln
B24: =IFERROR(VLOOKUP(C24,'字段信息'!A:C,3,),"") | C24: product_line_name | D24: =IFERROR(VLOOKUP(C24,'字段信息'!A:C,2,),"") | F24: =B24 | G24: √ | M24: 匹配产品线主数据进行判断 | N24: Doris | O24: ads.ads_fi_mr_accounts_rec_di dw.dwfi_im_td_product_category a3--产品线主数据 | P24: prdln_zh | Q24: a1.prdln=a3.prdln | R24: 产品线主数据需要现在enable_flag='T'
B25: =IFERROR(VLOOKUP(C25,'字段信息'!A:C,3,),"") | C25: cust_pay_term | D25: =IFERROR(VLOOKUP(C25,'字段信息'!A:C,2,),"") | F25: =B25 | G25: √ | M25: 直接对应 | N25: Doris | O25: ads.ads_fi_mr_accounts_rec_di ods.odsmf_cm_tab1065 a5 | P25: case when a5.zterm_c is null then '其他' else a5.zterm_c end | Q25: a1.zterm=a5.zterm
B26: =IFERROR(VLOOKUP(C26,'字段信息'!A:C,3,),"") | C26: data_scope_code | D26: =IFERROR(VLOOKUP(C26,'字段信息'!A:C,2,),"") | F26: =B26 | G26: √ | M26: 直接对应 | N26: Doris | O26: ads.ads_fi_mr_accounts_rec_di | P26: extent
B27: =IFERROR(VLOOKUP(C27,'字段信息'!A:C,3,),"") | C27: cust_code | D27: =IFERROR(VLOOKUP(C27,'字段信息'!A:C,2,),"") | F27: =B27 | G27: √ | L27: 普通级 | M27: 直接对应 | N27: Doris | O27: ads.ads_fi_mr_accounts_rec_di | P27: kunnr
B28: =IFERROR(VLOOKUP(C28,'字段信息'!A:C,3,),"") | C28: cust_name | D28: =IFERROR(VLOOKUP(C28,'字段信息'!A:C,2,),"") | F28: =B28 | G28: √ | L28: 普通级 | M28: 如果客户主数据匹配不到则取科目主数据 | N28: Doris | O28: ads.ads_fi_mr_accounts_rec_di 1、ods.ods_slt_s810_kna1-客户主数据 2、ods.odsslt_s810_skat-科目主数据 mandt = '810' and spras = '1' | P28: cust_name txt_20
B29: =IFERROR(VLOOKUP(C29,'字段信息'!A:C,3,),"") | C29: cust_branch_code | D29: =IFERROR(VLOOKUP(C29,'字段信息'!A:C,2,),"") | F29: =B29 | G29: √ | M29: 直接对应 | N29: Doris | O29: ads.ads_fi_mr_accounts_rec_di | P29: custfundcode
B30: =IFERROR(VLOOKUP(C30,'字段信息'!A:C,3,),"") | C30: cust_branch_name | D30: =IFERROR(VLOOKUP(C30,'字段信息'!A:C,2,),"") | F30: =B30 | G30: √ | M30: 直接对应 | N30: Doris | O30: ads.ads_fi_mr_accounts_rec_di | P30: custfundname
B31: =IFERROR(VLOOKUP(C31,'字段信息'!A:C,3,),"") | C31: cp_company_code | D31: =IFERROR(VLOOKUP(C31,'字段信息'!A:C,2,),"") | F31: =B31 | G31: √ | M31: 匹配客商映射对方公司dim.dim_rule_fi_mr_cust2ctp_mapping | N31: Doris | O31: dim.dim_rule_fi_mr_cust2ctp_mapping | P31: 优先取cp_company_code_mr，为空则取cp_company_code | Q31: 客商编码匹配客商映射对方公司映射表
B32: =IFERROR(VLOOKUP(C32,'字段信息'!A:C,3,),"") | C32: country_code | D32: =IFERROR(VLOOKUP(C32,'字段信息'!A:C,2,),"") | F32: =B32 | G32: √ | L32: 普通级 | M32: 1、先匹配SAP客户主数据得到zkunnr_mdg 2、再匹配mdg客户主数据得到对应字段 | N32: Doris | O32: 1、ods.ods_slt_s810_kna1-客户主数据 2、dw.dim_customer_base_info_dd-客户主数据基本信息 | P32: 1、zkunnr_mdg 2、country_code | Q32: 1、kunnr = kunnr 2、zkunnr_mdg = cust_code
B33: =IFERROR(VLOOKUP(C33,'字段信息'!A:C,3,),"") | C33: country_name | D33: =IFERROR(VLOOKUP(C33,'字段信息'!A:C,2,),"") | F33: =B33 | G33: √ | M33: 1、先匹配SAP客户主数据得到zkunnr_mdg 2、再匹配mdg客户主数据得到对应字段 | N33: Doris | O33: 1、ods.ods_slt_s810_kna1-客户主数据 2、dw.dim_customer_base_info_dd-客户主数据基本信息 | P33: 1、zkunnr_mdg 2、country_name | Q33: 1、kunnr = kunnr 2、zkunnr_mdg = cust_code
B34: =IFERROR(VLOOKUP(C34,'字段信息'!A:C,3,),"") | C34: channel_l1_code | D34: =IFERROR(VLOOKUP(C34,'字段信息'!A:C,2,),"") | F34: =B34 | G34: √ | M34: 1、先匹配SAP客户主数据得到zkunnr_mdg 2、再匹配mdg客户主数据得到对应字段 | N34: Doris | O34: 1、ods.ods_slt_s810_kna1-客户主数据 2、dw.dim_customer_base_info_dd-客户主数据基本信息 | P34: 1、zkunnr_mdg 2、com_1st_code | Q34: 1、kunnr = kunnr 2、zkunnr_mdg = cust_code
B35: =IFERROR(VLOOKUP(C35,'字段信息'!A:C,3,),"") | C35: channel_l1_name | D35: =IFERROR(VLOOKUP(C35,'字段信息'!A:C,2,),"") | F35: =B35 | G35: √ | M35: 1、先匹配SAP客户主数据得到zkunnr_mdg 2、再匹配mdg客户主数据得到对应字段 | N35: Doris | O35: 1、ods.ods_slt_s810_kna1-客户主数据 2、dw.dim_customer_base_info_dd-客户主数据基本信息 | P35: 1、zkunnr_mdg 2、com_1st_name | Q35: 1、kunnr = kunnr 2、zkunnr_mdg = cust_code
B36: =IFERROR(VLOOKUP(C36,'字段信息'!A:C,3,),"") | C36: channel_l2_code | D36: =IFERROR(VLOOKUP(C36,'字段信息'!A:C,2,),"") | F36: =B36 | G36: √ | M36: 1、先匹配SAP客户主数据得到zkunnr_mdg 2、再匹配mdg客户主数据得到对应字段 | N36: Doris | O36: 1、ods.ods_slt_s810_kna1-客户主数据 2、dw.dim_customer_base_info_dd-客户主数据基本信息 | P36: 1、zkunnr_mdg 2、com_2nd_code | Q36: 1、kunnr = kunnr 2、zkunnr_mdg = cust_code
B37: =IFERROR(VLOOKUP(C37,'字段信息'!A:C,3,),"") | C37: channel_l2_name | D37: =IFERROR(VLOOKUP(C37,'字段信息'!A:C,2,),"") | F37: =B37 | G37: √ | M37: 1、先匹配SAP客户主数据得到zkunnr_mdg 2、再匹配mdg客户主数据得到对应字段 | N37: Doris | O37: 1、ods.ods_slt_s810_kna1-客户主数据 2、dw.dim_customer_base_info_dd-客户主数据基本信息 | P37: 1、zkunnr_mdg 2、com_2nd_name | Q37: 1、kunnr = kunnr 2、zkunnr_mdg = cust_code
B38: =IFERROR(VLOOKUP(C38,'字段信息'!A:C,3,),"") | C38: channel_l3_code | D38: =IFERROR(VLOOKUP(C38,'字段信息'!A:C,2,),"") | F38: =B38 | G38: √ | M38: 1、先匹配SAP客户主数据得到zkunnr_mdg 2、再匹配mdg客户主数据得到对应字段 | N38: Doris | O38: 1、ods.ods_slt_s810_kna1-客户主数据 2、dw.dim_customer_base_info_dd-客户主数据基本信息 | P38: 1、zkunnr_mdg 2、com_3rd_code | Q38: 1、kunnr = kunnr 2、zkunnr_mdg = cust_code
B39: =IFERROR(VLOOKUP(C39,'字段信息'!A:C,3,),"") | C39: channel_l3_name | D39: =IFERROR(VLOOKUP(C39,'字段信息'!A:C,2,),"") | F39: =B39 | G39: √ | M39: 1、先匹配SAP客户主数据得到zkunnr_mdg 2、再匹配mdg客户主数据得到对应字段 | N39: Doris | O39: 1、ods.ods_slt_s810_kna1-客户主数据 2、dw.dim_customer_base_info_dd-客户主数据基本信息 | P39: 1、zkunnr_mdg 2、com_3rd_name | Q39: 1、kunnr = kunnr 2、zkunnr_mdg = cust_code
B40: =IFERROR(VLOOKUP(C40,'字段信息'!A:C,3,),"") | C40: bus_range_code | D40: =IFERROR(VLOOKUP(C40,'字段信息'!A:C,2,),"") | F40: =B40 | G40: √
...

Sheet dwd_fi_mr_ar_writeoff_mi
A1: 返回 | B1: dwd_fi_mr_ar_writeoff_mi逻辑处理
A2: 规则库 | B2: 表名称 | C2: dwd.dwd_fi_mr_ar_writeoff_mi
B3: 表描述 | C3: 核销金额明细表 | D3: 表类型 | E3: 事实表 | F3: 数仓分层 | G3: DWD
B4: L1数仓目录 | C4: 管理财经 | D4: L2数仓目录 | E4: 财报管理 | F4: L3数仓目录 | G4: 应收
B5: 更新方式 | C5: 增量更新 | D5: 设计人员 | F5: 时间
B6: 使用场景 | C6: 取财务中台中坏账核销单中的核销金额数据
B7: 目标表 | M7: 财务中台坏账核销单
B8: 字段中文名称 | C8: *字段名称 | D8: *类型 | E8: 主键 | F8: *描述 | G8: 允许为空 | H8: 默认值 | I8: 聚合类型 | J8: 基础标准 | K8: 标准代码 | L8: *安全分级 | M8: 转换清洗规则 | N8: 源系统 | O8: 源头表 | P8: 源头字段 | Q8: 匹配字段 | R8: 匹配过滤 | S8: 数仓处理脚本 | T8: 备注
B9: =IFERROR(VLOOKUP(C9,'字段信息'!A:C,3,),"") | C9: dt_month | D9: =IFERROR(VLOOKUP(C9,'字段信息'!A:C,2,),"") | F9: =B9 | M9: 限制条件： 1、限制科目为应收、其他应收、长期应收、合同资产 2、单据状态fbillstatus = 'C' 3、SAP凭证号fk_hifi_sapvouchernum 不为空 | N9: 参数年月 | O9: ods.odsfmfi_tk_hifi_baddebtverify ods.odsfmfi_t_bd_period | P9: 参数截取年月 | Q9: fk_hifi_accountdate = fid | R9: fnumber=参数年月 ods.ODSFMFI_TK_HIFI_BADDEBTVERIFY.fbillstatus = 'C' ods.ODSFMFI_TK_HIFI_BADDEBTVERIFY.fk_hifi_sapvouchernum IS NOT NULL ( (r.fk_hifi_sap_version = 'SAP600' AND (a.fnumber LIKE '1122%' OR a.fnumber LIKE '1221%' OR a.fnumber LIKE '1531%' OR a.fnumber = '1460000000')) OR (r.fk_hifi_sap_version = 'SAP700' AND (a.fnumber LIKE '1122%' OR a.fnumber LIKE '1221%' OR a.fnumber = '1460000000')) OR (r.fk_hifi_sap_version = 'SAP900' AND (a.fnumber LIKE '1131%' OR a.fnumber LIKE '1133%' OR a.fnumber = '1460000000')) OR (r.fk_hifi_sap_version = 'SAP800B'AND (a.fnumber LIKE '1122%' OR a.fnumber LIKE '1221%' OR a.fnumber = '1460000000')) OR (r.fk_hifi_sap_version = 'SAP800' AND (a.fnumber LIKE '1131%' OR a.fnumber LIKE '1133%' OR a.fnumber = '1460000000')) OR (r.fk_hifi_sap_version = 'SAP810' AND (a.fnumber LIKE '1122%' OR a.fnumber LIKE '1221%')) ) | S9: r:ods.ODSFMSECD_TK_HIFI_ORGS_REF匹配sap版本号fk_hifi_org_id=fid a:匹配科目主数据ods.ODSFMFI_T_BD_ACCOUNT fk_hifi_accountorg = fid
B10: =IFERROR(VLOOKUP(C10,'字段信息'!A:C,3,),"") | C10: year | D10: =IFERROR(VLOOKUP(C10,'字段信息'!A:C,2,),"") | F10: =B10 | G10: √ | M10: 直接对应 | N10: 参数年 | P10: 参数截取年份
B11: =IFERROR(VLOOKUP(C11,'字段信息'!A:C,3,),"") | C11: month | D11: =IFERROR(VLOOKUP(C11,'字段信息'!A:C,2,),"") | F11: =B11 | G11: √ | L11: 普通级 | M11: 直接对应 | N11: 参数月 | P11: 参数截取月份
B12: =IFERROR(VLOOKUP(C12,'字段信息'!A:C,3,),"") | C12: company_code | D12: =IFERROR(VLOOKUP(C12,'字段信息'!A:C,2,),"") | F12: =B12 | G12: √ | L12: 普通级 | M12: 匹配公司主数据 | N12: Doris | O12: ods.odsfmfi_tk_hifi_baddebtverify ods.odsfmtss_t_org_org | P12: ods.odsfmtss_t_org_org.fnumber | Q12: fk_hifi_accountorg = fid
B13: =IFERROR(VLOOKUP(C13,'字段信息'!A:C,3,),"") | C13: acct_src_code | D13: =IFERROR(VLOOKUP(C13,'字段信息'!A:C,2,),"") | F13: =B13 | M13: 直接对应 | N13: Doris | O13: ods.odsfmfi_tk_hifi_baddebtverifysub ods.odsfmfi_t_bd_account | P13: fnumber | Q13: fk_hifi_subjects = fid
A14: 0908：科目分类的处理后续统一处理，D层放原始科目 | B14: =IFERROR(VLOOKUP(C14,'字段信息'!A:C,3,),"") | C14: acct_map_code | D14: =IFERROR(VLOOKUP(C14,'字段信息'!A:C,2,),"") | F14: =B14 | G14: √ | L14: 普通级 | M14: 匹配科目映射表dim.dim_rule_fi_mr_acct_mapping | N14: Doris | O14: dim.dim_rule_fi_mr_acct_mapping | P14: 取映射后科目 | Q14: 科目编码匹配科目映射表 | S14: case when a.fnumber LIKE '1122%' OR a.fnumber LIKE '1131%' then '1122000000' when a.fnumber LIKE '1221%' OR a.fnumber LIKE '1133%' then '122101F' when a.fnumber = '1460000000' then '1460000000' when a.fnumber LIKE '1531%' then '1531000000' END
B15: =IFERROR(VLOOKUP(C15,'字段信息'!A:C,3,),"") | C15: cust_code | D15: =IFERROR(VLOOKUP(C15,'字段信息'!A:C,2,),"") | F15: =B15 | G15: √ | L15: 普通级 | M15: 匹配客户主数据 | N15: Doris | O15: ods.odsfmfi_tk_hifi_baddebtverifysub ods.odsfmtss_t_bd_customer | P15: SUBSTR(cus.fnumber,1,INSTR(cus.fnumber,'(')-1) | Q15: fk_hifi_customer = fid
B16: =IFERROR(VLOOKUP(C16,'字段信息'!A:C,3,),"") | C16: cust_name | D16: =IFERROR(VLOOKUP(C16,'字段信息'!A:C,2,),"") | F16: =B16 | G16: √ | L16: 普通级 | M16: 匹配客户主数据 | N16: Doris | O16: ods.odsfmfi_tk_hifi_baddebtverifysub ods.odsfmtss_t_bd_customer | P16: fname | Q16: fk_hifi_customer = fid
B17: =IFERROR(VLOOKUP(C17,'字段信息'!A:C,3,),"") | C17: src_profitcenter_code | D17: =IFERROR(VLOOKUP(C17,'字段信息'!A:C,2,),"") | F17: =B17 | G17: √ | M17: 匹配利润中心主数据 | N17: Doris | O17: ods.odsfmfi_tk_hifi_baddebtverifysub ods.odsfmfi_tk_hifi_cas_profitcenter | P17: ltrim(pf.fnumber,'0') | Q17: fk_hifi_profitcenter = fid
